Workbook

Sheet Profile Requests
A1: Name of Institute | B1: Reporting Authority | C1: Name | D1: Designation | E1: Moble Nmber | F1: Email | G1: User Roles | H1: Org Id | I1: Pass

Sheet Sum
C1: Report From
B2: All Sum of Tehsil Talwandi Sabo | E2: ='Tehsil Reports'!N1 -> 44921 | F2: To | G2: ='Tehsil Reports'!Q1 -> 44951
B3: NEW CASES EQUINE | C3: NEW CASES BOVINE | D3: NEW CASES OTHERS | E3: NEW CASES DOGS | F3: OLD CASES EQUINE | G3: OLD CASES BOVINE | H3: OLD CASES OTHERS | I3: OLD CASES DOGS | J3: TREATED IN CAMP EQUINE | K3: TREATED IN CAMP BOVINE | L3: TREATED IN CAMP OTHERS | M3: TREATED IN CAMP DOGS | N3: BOVINE CASTRATIONS | O3: OTHERS CASTRATIONS | P3: Number of Pregnancy Diagnosis (OTHER THEN FALLOWUP) | Q3: A.H. Certificate Small Animals | R3: A.H. Certificate Large Animals | S3: Post Mortem Small Animals | T3: Post Mortem Large Animals | U3: Post Mortem Vetro Legal | V3: H.S. Vaccine Doses Received | W3: H.S. Vaccine Doses Used | X3: H.S. Vaccine Animal Vaccinated | Y3: FMD. Vaccine Doses Received | Z3: FMD. Vaccine Doses Used | AA3: FMD. Vaccine Animal Vaccinated | AB3: Black Quarter Doses Received | AC3: Black Quarter Doses Used | AD3: Black Quarter Animal Vaccinated | AE3: Brucellosis Vaccine Doses Received | AF3: Brucellosis Vaccine Doses Used | AG3: Brucellosis Vaccine Animal Vaccinated | AH3: Entero Toximia Vaccine Doses Received | AI3: Entero Toximia Vaccine Doses Used | AJ3: Entero Toximia Vaccine Animals Vaccinated | AK3: Theilaria Vaccine Doses Received | AL3: Theilaria Vaccine Doses Used | AM3: Theilaria Vaccine Animal Vaccinated | AN3: Rabies Vaccine Doses Received | AO3: Rabies Vaccine Doses Used | AP3: Rabies Vaccine Animal Vaccinated | AQ3: AI Done With HF Straws | AR3: AI Done With Jersey Straws | AS3: AI Done With Cross Breed Straws | AT3: AI Done With Sahiwal Straws | AU3: Cow Cover With HF Straws | AV3: Cow Cover With Jersey Straws | AW3: Cow Cover With Cross Breed Straws | AX3: Cow Cover With Sahiwal Straws | AY3: AI Done With HF ETT Straws | AZ3: AI Done With Jersey ETT Straws | BA3: AI Done With Imported HF Straws | BB3: AI Done With Imported Jersey Straws | BC3: Cow Cover With HF ETT Straws | BD3: Cow Cover With Jersey ETT Straws | BE3: Cow Cover With Imported HF Straws | BF3: Cow Cover With Imported Jersey Straws | BG3: AI Done With Sexed Straws | BH3: Cow Cover With Sexed Straws | BI3: AI Done With Murrah Straws | BJ3: AI Done With Nili-Ravi Straws | BK3: Buffalo Cover With Murrah Straws | BL3: Buffalo Cover With Nili-Ravi Straws | BM3: HF Cow Tested | BN3: HF Cow Tested and Found Postive | BO3: Jersey Cow Tested | BP3: Jersey Cow Tested and Found Postive | BQ3: Cross Breed Cow Tested | BR3: Cross Breed Cow Tested and Found Postive | BS3: Sahiwal Cow Tested | BT3: Sahiwal Cow Tested and Found Postive | BU3: HF ETT Cow Tested | BV3: HF ETT Cow Tested and Found Postive | BW3: Jessey ETT Cow Tested | BX3: Jessey ETT Cow Tested and Found Postive | BY3: Imported HF Cow Tested | BZ3: Imported HF Cow Tested and Found Postive | CA3: Imported Jersey Cow Tested | CB3: Imported Jersey Cow Tested and Found Postive | CC3: Sexed Semon Cows Tested | CD3: Sexed Semon Cows Found Postive | CE3: Murah Tested | CF3: Murah Tested and Found Postive | CG3: Nili Ravi Tested | CH3: Nili Tested and Found Postive | CI3: HF Male Calves | CJ3: HF female Calves | CK3: Jersey Male Calves | CL3: Jersey Cow female Calves | CM3: Cross Breed Male Calves | CN3: Cross Breed Cow female Calves | CO3: Sahiwal Male Calves | CP3: Sahiwal female Calves | CQ3: HF ETT Male Calves | CR3: HF ETT female Calves | CS3: Jersey ETT Male Calves | CT3: Jersey ETT female Calves | CU3: Imported HF Male Calves | CV3: Imported HF female Calves | CW3: Imported Jersey Male Calves | CX3: Imported Jersey Cow female Calves | CY3: Sexed Semon Cow Male Calves | CZ3: Sexed Semon Cow Female Calves | DA3: Murrah Male Calves | DB3: Murrah Female Calves | DC3: Nili Ravi Male Calves | DD3: Nili Ravi Female Calves | DE3: HF Straws Used INAPH during month | DF3: Jesey Straws Used INAPH during month | DG3: Cross Breed Straws Used INAPH during month | DH3: Sahiwal Straws Used INAPH during month | DI3: HF ETT Straws Used INAPH during month | DJ3: Jersey ETT Straws Used INAPH during month | DK3: Imported HF Straws Used INAPH during month | DL3: Imported Jersey Straws Used INAPH during month | DM3: Sexed Straws Used INAPH during month | DN3: Murrah Straws Used INAPH during month | DO3: Nili Ravi Straws Used INAPH during month | DP3: HF Straws Issued to AIW during Month | DQ3: Jesey Straws Issued to AIW during Month | DR3: Cross Breed Straws Issued to AIW during Month | DS3: Sahiwal Straws Issued to AIW during Month | DT3: HF ETT Straws Issued to AIW during Month | DU3: Jersey ETT Straws Issued to AIW during Month | DV3: Imported HF Straws Issued to AIW during Month | DW3: Imported Jersey Straws Issued to AIW during Month | DX3: Sexed Straws Issued to AIW during Month | DY3: Murrah Straws Issued to AIW during Month | DZ3: Nili Ravi Straws Issued to AIW during Month | EA3: HF Straws Received During Month | EB3: Jesey Straws Received During Month | EC3: Cross Breed Straws Received During Month | ED3: Sahiwal Straws Received During Month | EE3: HF ETT Straws Received During Month | EF3: Jersey ETT Straws Received During Month | EG3: Imported HF Straws Received During Month | EH3: Imported Jersey Straws Received During Month | EI3: Sexed Straws Received During Month | EJ3: Murrah Straws Received During Month | EK3: Nili Ravi Straws Received During Month
A4: This Month | B4: =sumifs('Form responses'!G2:G53,'Form responses'!$C$2:$C53,">="&$E$2,'Form responses'!$C$2:$C53,"<="&$G$2) -> 0 | C4: =sumifs('Form responses'!H2:H53,'Form responses'!$C$2:$C53,">="&$E$2,'Form responses'!$C$2:$C53,"<="&$G$2) -> 0 | D4: =sumifs('Form responses'!I2:I53,'Form responses'!$C$2:$C53,">="&$E$2,'Form responses'!$C$2:$C53,"<="&$G$2) -> 0 | E4: =sumifs('Form responses'!J2:J53,'Form responses'!$C$2:$C53,">="&$E$2,'Form responses'!$C$2:$C53,"<="&$G$2) -> 0 | F4: =sumifs('Form responses'!K2:K53,'Form responses'!$C$2:$C53,">="&$E$2,'Form responses'!$C$2:$C53,"<="&$G$2) -> 0 | G4: =sumifs('Form responses'!L2:L53,'Form responses'!$C$2:$C53,">="&$E$2,'Form responses'!$C$2:$C53,"<="&$G$2) -> 0 | H4: =sumifs('Form responses'!M2:M53,'Form responses'!$C$2:$C53,">="&$E$2,'Form responses'!$C$2:$C53,"<="&$G$2) -> 0 | I4: =sumifs('Form responses'!N2:N53,'Form responses'!$C$2:$C53,">="&$E$2,'Form responses'!$C$2:$C53,"<="&$G$2) -> 0 | ... EK4: =sumifs('Form responses'!EP2:EP53,'Form responses'!$C$2:$C53,">="&$E$2,'Form responses'!$C$2:$C53,"<="&$G$2) -> 0
A5: This Year | B5: =sumifs('Form responses'!G2:G53,'Form responses'!$C$2:$C53,"<="&$G$2,'Form responses'!$C$2:$C53,">="&Date(YEAR(DATE(YEAR($E$2),MONTH($E$2)+(-3),1)),4,1)) -> 0 | C5: =sumifs('Form responses'!H2:H53,'Form responses'!$C$2:$C53,"<="&$G$2,'Form responses'!$C$2:$C53,">="&Date(YEAR(DATE(YEAR($E$2),MONTH($E$2)+(-3),1)),4,1)) -> 0 | D5: =sumifs('Form responses'!I2:I53,'Form responses'!$C$2:$C53,"<="&$G$2,'Form responses'!$C$2:$C53,">="&Date(YEAR(DATE(YEAR($E$2),MONTH($E$2)+(-3),1)),4,1)) -> 0 | E5: =sumifs('Form responses'!J2:J53,'Form responses'!$C$2:$C53,"<="&$G$2,'Form responses'!$C$2:$C53,">="&Date(YEAR(DATE(YEAR($E$2),MONTH($E$2)+(-3),1)),4,1)) -> 0 | F5: =sumifs('Form responses'!K2:K53,'Form responses'!$C$2:$C53,"<="&$G$2,'Form responses'!$C$2:$C53,">="&Date(YEAR(DATE(YEAR($E$2),MONTH($E$2)+(-3),1)),4,1)) -> 0 | G5: =sumifs('Form responses'!L2:L53,'Form responses'!$C$2:$C53,"<="&$G$2,'Form responses'!$C$2:$C53,">="&Date(YEAR(DATE(YEAR($E$2),MONTH($E$2)+(-3),1)),4,1)) -> 0 | H5: =sumifs('Form responses'!M2:M53,'Form responses'!$C$2:$C53,"<="&$G$2,'Form responses'!$C$2:$C53,">="&Date(YEAR(DATE(YEAR($E$2),MONTH($E$2)+(-3),1)),4,1)) -> 0 | I5: =sumifs('Form responses'!N2:N53,'Form responses'!$C$2:$C53,"<="&$G$2,'Form responses'!$C$2:$C53,">="&Date(YEAR(DATE(YEAR($E$2),MONTH($E$2)+(-3),1)),4,1)) -> 0 | ... EK5: =sumifs('Form responses'!EP2:EP53,'Form responses'!$C$2:$C53,"<="&$G$2,'Form responses'!$C$2:$C53,">="&Date(YEAR(DATE(YEAR($E$2),MONTH($E$2)+(-3),1)),4,1)) -> 0
B7: Service Charges of this month
B8: OPD Case Fees | C8: OPD Case Dogs Fees | D8: Pregnency Diagnose Fee | E8: Castration Fee | F8: Health certificate Fee small animals | G8: Health certificate Fee Large animals | H8: Post Mortum Fee small animals | I8: Post Mortum Fee Large animals | J8: HS Vaccine fee | K8: FMD Vaccine Fee | L8: BQ Vaccine fee | M8: Brucellosis Vaccine Fee | N8: Theilaria Vaccine Fee | O8: Rabies Vaccine Fee | P8: ETV vaccine Fee | Q8: AI Cow Fee (Local semon) | R8: Ai Cow Fee (ETT Semon) | S8: AI Cow Fee (Imported Semon) | T8: AI Cow Fee (Sexed Semon) | U8: AI Fee Buffalow | V8: Faecal test Fee | W8: Blood Test Fee | X8: Urine Test Fee | Y8: Milk Test Fee | Z8: Post Mortum Fee Vetro legal
A9: This Month | B9: =sumifs(fees!C$2:C53,fees!$B$2:$B53,">="&$E$2,fees!$B$2:$B53,"<="&$G$2) -> 10 | C9: =sumifs(fees!D$2:D53,fees!$B$2:$B53,">="&$E$2,fees!$B$2:$B53,"<="&$G$2) -> 50 | D9: =sumifs(fees!E$2:E53,fees!$B$2:$B53,">="&$E$2,fees!$B$2:$B53,"<="&$G$2) -> 25 | E9: =sumifs(fees!F$2:F53,fees!$B$2:$B53,">="&$E$2,fees!$B$2:$B53,"<="&$G$2) -> 50 | F9: =sumifs(fees!G$2:G53,fees!$B$2:$B53,">="&$E$2,fees!$B$2:$B53,"<="&$G$2) -> 50 | G9: =sumifs(fees!H$2:H53,fees!$B$2:$B53,">="&$E$2,fees!$B$2:$B53,"<="&$G$2) -> 100 | H9: =sumifs(fees!I$2:I53,fees!$B$2:$B53,">="&$E$2,fees!$B$2:$B53,"<="&$G$2) -> 20 | I9: =sumifs(fees!J$2:J53,fees!$B$2:$B53,">="&$E$2,fees!$B$2:$B53,"<="&$G$2) -> 100 | ... Z9: =sumifs(fees!AA$2:AA53,fees!$B$2:$B53,">="&$E$2,fees!$B$2:$B53,"<="&$G$2) -> 200
B11: Faecal test | C11: Fee | D11: Blood Test | E11: Fee | F11: Urine Test | G11: Fee | H11: Milk Test | I11: Fee | J11: Total fees
A12: This Month | B12: =sumifs('Form responses'!EQ2:EQ53,'Form responses'!$B$2:$B53,">="&$E$2,'Form responses'!$C$2:$C53,"<="&$G$2) -> 0 | C12: =B12*$V$9 -> 0 | D12: =sumifs('Form responses'!ER2:ER53,'Form responses'!$B$2:$B53,">="&$E$2,'Form responses'!$C$2:$C53,"<="&$G$2) -> 0 | E12: =D12*$W$9 -> 0 | F12: =sumifs('Form responses'!ES2:ES53,'Form responses'!$B$2:$B53,">="&$E$2,'Form responses'!$C$2:$C53,"<="&$G$2) -> 0 | G12: =F12*$X$9 -> 0 | H12: =sumifs('Form responses'!ET2:ET53,'Form responses'!$B$2:$B53,">="&$E$2,'Form responses'!$C$2:$C53,"<="&$G$2) -> 0 | I12: =H12*$Y$9 -> 0 | J12: =C12+E12+G12+I12 -> 0
A13: This Year | B13: =sumifs('Form responses'!EQ2:EQ53,'Form responses'!$B$2:$B53,">="&Date(YEAR(DATE(YEAR($G$2),MONTH($G$2)+(-3),1)),4,1),'Form responses'!$C$2:$C53,"<="&$G$2) -> 0 | C13: =B13*$V$9 -> 0 | D13: =sumifs('Form responses'!ER2:ER53,'Form responses'!$B$2:$B53,">="&Date(YEAR(DATE(YEAR($G$2),MONTH($G$2)+(-3),1)),4,1),'Form responses'!$C$2:$C53,"<="&$G$2) -> 0 | E13: =D13*$W$9 -> 0 | F13: =sumifs('Form responses'!ES2:ES53,'Form responses'!$B$2:$B53,">="&Date(YEAR(DATE(YEAR($G$2),MONTH($G$2)+(-3),1)),4,1),'Form responses'!$C$2:$C53,"<="&$G$2) -> 0 | G13: =F13*$X$9 -> 0 | H13: =sumifs('Form responses'!ET2:ET53,'Form responses'!$B$2:$B53,">="&Date(YEAR(DATE(YEAR($G$2),MONTH($G$2)+(-3),1)),4,1),'Form responses'!$C$2:$C53,"<="&$G$2) -> 0 | I13: =H13*$Y$9 -> 0 | J13: =C12+E12+G12+I12 -> 0
B16: Institute Sum of Tehsil Talwandi Sabo | E16: =E2 -> 44921 | F16: To | G16: =G2 -> 44951
B17: AI Done With HF Straws | C17: AI Done With Jersey Straws | D17: AI Done With Cross Breed Straws | E17: AI Done With Sahiwal Straws | F17: Cow Cover With HF Straws | G17: Cow Cover With Jersey Straws | H17: Cow Cover With Cross Breed Straws | I17: Cow Cover With Sahiwal Straws | J17: AI Done With HF ETT Straws | K17: AI Done With Jersey ETT Straws | L17: AI Done With Imported HF Straws | M17: AI Done With Imported Jersey Straws | N17: Cow Cover With HF ETT Straws | O17: Cow Cover With Jersey ETT Straws | P17: Cow Cover With Imported HF Straws | Q17: Cow Cover With Imported Jersey Straws | R17: AI Done With Sexed Straws | S17: Cow Cover With Sexed Straws | T17: AI Done With Murrah Straws | U17: AI Done With Nili-Ravi Straws | V17: Buffalo Cover With Murrah Straws | W17: Buffalo Cover With Nili-Ravi Straws | X17: HF Cow Tested | Y17: HF Cow Tested and Found Postive | Z17: Jersey Cow Tested | AA17: Jersey Cow Tested and Found Postive | AB17: Cross Breed Cow Tested | AC17: Cross Breed Cow Tested and Found Postive | AD17: Sahiwal Cow Tested | AE17: Sahiwal Cow Tested and Found Postive | AF17: HF ETT Cow Tested | AG17: HF ETT Cow Tested and Found Postive | AH17: Jessey ETT Cow Tested | AI17: Jessey ETT Cow Tested and Found Postive | AJ17: Imported HF Cow Tested | AK17: Imported HF Cow Tested and Found Postive | AL17: Imported Jersey Cow Tested | AM17: Imported Jersey Cow Tested and Found Postive | AN17: Sexed Semon Cows Tested | AO17: Sexed Semon Cows Found Postive | AP17: Murah Tested | AQ17: Murah Tested and Found Postive | AR17: Nili Ravi Tested | AS17: Nili Tested and Found Postive | AT17: HF Male Calves | AU17: HF female Calves | AV17: Jersey Male Calves | AW17: Jersey Cow female Calves | AX17: Cross Breed Male Calves | AY17: Cross Breed Cow female Calves | AZ17: Sahiwal Male Calves | BA17: Sahiwal female Calves | BB17: HF ETT Male Calves | BC17: HF ETT female Calves | BD17: Jersey ETT Male Calves | BE17: Jersey ETT female Calves | BF17: Imported HF Male Calves | BG17: Imported HF female Calves | BH17: Imported Jersey Male Calves | BI17: Imported Jersey Cow female Calves | BJ17: Sexed Semon Cow Male Calves | BK17: Sexed Semon Cow Female Calves | BL17: Murrah Male Calves | BM17: Murrah Female Calves | BN17: Nili Ravi Male Calves | BO17: Nili Ravi Female Calves | BP17: HF Straws Used INAPH during month | BQ17: Jesey Straws Used INAPH during month | BR17: Cross Breed Straws Used INAPH during month | BS17: Sahiwal Straws Used INAPH during month | BT17: HF ETT Straws Used INAPH during month | BU17: Jersey ETT Straws Used INAPH during month | BV17: Imported HF Straws Used INAPH during month | BW17: Imported Jersey Straws Used INAPH during month | BX17: Sexed Straws Used INAPH during month | BY17: Murrah Straws Used INAPH during month | BZ17: Nili Ravi Straws Used INAPH during month | CA17: HF Straws Issued to AIW during Month | CB17: Jesey Straws Issued to AIW during Month | CC17: Cross Breed Straws Issued to AIW during Month | CD17: Sahiwal Straws Issued to AIW during Month | CE17: HF ETT Straws Issued to AIW during Month | CF17: Jersey ETT Straws Issued to AIW during Month | CG17: Imported HF Straws Issued to AIW during Month | CH17: Imported Jersey Straws Issued to AIW during Month | CI17: Sexed Straws Issued to AIW during Month | CJ17: Murrah Straws Issued to AIW during Month | CK17: Nili Ravi Straws Issued to AIW during Month | CL17: HF Straws Received During Month | CM17: Jesey Straws Received During Month | CN17: Cross Breed Straws Received During Month | CO17: Sahiwal Straws Received During Month | CP17: HF ETT Straws Received During Month | CQ17: Jersey ETT Straws Received During Month | CR17: Imported HF Straws Received During Month | CS17: Imported Jersey Straws Received During Month | CT17: Sexed Straws Received During Month | CU17: Murrah Straws Received During Month | CV17: Nili Ravi Straws Received During Month
A18: This Month | B18: =sumifs('Form responses'!AV2:AV53,'Form responses'!$C$2:$C53,">="&$E$2,'Form responses'!$C$2:$C53,"<="&$G$2,'Form responses'!$F$2:$F53,"<>4") -> 0 | C18: =sumifs('Form responses'!AW2:AW53,'Form responses'!$C$2:$C53,">="&$E$2,'Form responses'!$C$2:$C53,"<="&$G$2,'Form responses'!$F$2:$F53,"<>4") -> 0 | D18: =sumifs('Form responses'!AX2:AX53,'Form responses'!$C$2:$C53,">="&$E$2,'Form responses'!$C$2:$C53,"<="&$G$2,'Form responses'!$F$2:$F53,"<>4") -> 0 | E18: =sumifs('Form responses'!AY2:AY53,'Form responses'!$C$2:$C53,">="&$E$2,'Form responses'!$C$2:$C53,"<="&$G$2,'Form responses'!$F$2:$F53,"<>4") -> 0 | F18: =sumifs('Form responses'!AZ2:AZ53,'Form responses'!$C$2:$C53,">="&$E$2,'Form responses'!$C$2:$C53,"<="&$G$2,'Form responses'!$F$2:$F53,"<>4") -> 0 | G18: =sumifs('Form responses'!BA2:BA53,'Form responses'!$C$2:$C53,">="&$E$2,'Form responses'!$C$2:$C53,"<="&$G$2,'Form responses'!$F$2:$F53,"<>4") -> 0 | H18: =sumifs('Form responses'!BB2:BB53,'Form responses'!$C$2:$C53,">="&$E$2,'Form responses'!$C$2:$C53,"<="&$G$2,'Form responses'!$F$2:$F53,"<>4") -> 0 | I18: =sumifs('Form responses'!BC2:BC53,'Form responses'!$C$2:$C53,">="&$E$2,'Form responses'!$C$2:$C53,"<="&$G$2,'Form responses'!$F$2:$F53,"<>4") -> 0 | ... CV18: =sumifs('Form responses'!EP2:EP53,'Form responses'!$C$2:$C53,">="&$E$2,'Form responses'!$C$2:$C53,"<="&$G$2,'Form responses'!$F$2:$F53,"<>4") -> 0
A19: This Year | B19: =sumifs('Form responses'!AV2:AV53,'Form responses'!$C$2:$C53,"<="&$G$2,'Form responses'!$C$2:$C53,">="&Date(YEAR(DATE(YEAR($G$2),MONTH($G$2)+(-3),1)),4,1),'Form responses'!$F$2:$F53,"<>4") -> 0 | C19: =sumifs('Form responses'!AW2:AW53,'Form responses'!$C$2:$C53,"<="&$G$2,'Form responses'!$C$2:$C53,">="&Date(YEAR(DATE(YEAR($G$2),MONTH($G$2)+(-3),1)),4,1),'Form responses'!$F$2:$F53,"<>4") -> 0 | D19: =sumifs('Form responses'!AX2:AX53,'Form responses'!$C$2:$C53,"<="&$G$2,'Form responses'!$C$2:$C53,">="&Date(YEAR(DATE(YEAR($G$2),MONTH($G$2)+(-3),1)),4,1),'Form responses'!$F$2:$F53,"<>4") -> 0 | E19: =sumifs('Form responses'!AY2:AY53,'Form responses'!$C$2:$C53,"<="&$G$2,'Form responses'!$C$2:$C53,">="&Date(YEAR(DATE(YEAR($G$2),MONTH($G$2)+(-3),1)),4,1),'Form responses'!$F$2:$F53,"<>4") -> 0 | F19: =sumifs('Form responses'!AZ2:AZ53,'Form responses'!$C$2:$C53,"<="&$G$2,'Form responses'!$C$2:$C53,">="&Date(YEAR(DATE(YEAR($G$2),MONTH($G$2)+(-3),1)),4,1),'Form responses'!$F$2:$F53,"<>4") -> 0 | G19: =sumifs('Form responses'!BA2:BA53,'Form responses'!$C$2:$C53,"<="&$G$2,'Form responses'!$C$2:$C53,">="&Date(YEAR(DATE(YEAR($G$2),MONTH($G$2)+(-3),1)),4,1),'Form responses'!$F$2:$F53,"<>4") -> 0 | H19: =sumifs('Form responses'!BB2:BB53,'Form responses'!$C$2:$C53,"<="&$G$2,'Form responses'!$C$2:$C53,">="&Date(YEAR(DATE(YEAR($G$2),MONTH($G$2)+(-3),1)),4,1),'Form responses'!$F$2:$F53,"<>4") -> 0 | I19: =sumifs('Form responses'!BC2:BC53,'Form responses'!$C$2:$C53,"<="&$G$2,'Form responses'!$C$2:$C53,">="&Date(YEAR(DATE(YEAR($G$2),MONTH($G$2)+(-3),1)),4,1),'Form responses'!$F$2:$F53,"<>4") -> 0 | ... CV19: =sumifs('Form responses'!EP2:EP53,'Form responses'!$C$2:$C53,"<="&$G$2,'Form responses'!$C$2:$C53,">="&Date(YEAR(DATE(YEAR($G$2),MONTH($G$2)+(-3),1)),4,1),'Form responses'!$F$2:$F53,"<>4") -> 0
B22: Sum PAW of Tehsil Talwandi Sabo | E22: =E16 -> 44921 | F22: To | G22: =G16 -> 44951
B23: AI Done With HF Straws | C23: AI Done With Jersey Straws | D23: AI Done With Cross Breed Straws | E23: AI Done With Sahiwal Straws | F23: Cow Cover With HF Straws | G23: Cow Cover With Jersey Straws | H23: Cow Cover With Cross Breed Straws | I23: Cow Cover With Sahiwal Straws | J23: AI Done With HF ETT Straws | K23: AI Done With Jersey ETT Straws | L23: AI Done With Imported HF Straws | M23: AI Done With Imported Jersey Straws | N23: Cow Cover With HF ETT Straws | O23: Cow Cover With Jersey ETT Straws | P23: Cow Cover With Imported HF Straws | Q23: Cow Cover With Imported Jersey Straws | R23: AI Done With Sexed Straws | S23: Cow Cover With Sexed Straws | T23: AI Done With Murrah Straws | U23: AI Done With Nili-Ravi Straws | V23: Buffalo Cover With Murrah Straws | W23: Buffalo Cover With Nili-Ravi Straws | X23: HF Cow Tested | Y23: HF Cow Tested and Found Postive | Z23: Jersey Cow Tested | AA23: Jersey Cow Tested and Found Postive | AB23: Cross Breed Cow Tested | AC23: Cross Breed Cow Tested and Found Postive | AD23: Sahiwal Cow Tested | AE23: Sahiwal Cow Tested and Found Postive | AF23: HF ETT Cow Tested | AG23: HF ETT Cow Tested and Found Postive | AH23: Jessey ETT Cow Tested | AI23: Jessey ETT Cow Tested and Found Postive | AJ23: Imported HF Cow Tested | AK23: Imported HF Cow Tested and Found Postive | AL23: Imported Jersey Cow Tested | AM23: Imported Jersey Cow Tested and Found Postive | AN23: Sexed Semon Cows Tested | AO23: Sexed Semon Cows Found Postive | AP23: Murah Tested | AQ23: Murah Tested and Found Postive | AR23: Nili Ravi Tested | AS23: Nili Tested and Found Postive | AT23: HF Male Calves | AU23: HF female Calves | AV23: Jersey Male Calves | AW23: Jersey Cow female Calves | AX23: Cross Breed Male Calves | AY23: Cross Breed Cow female Calves | AZ23: Sahiwal Male Calves | BA23: Sahiwal female Calves | BB23: HF ETT Male Calves | BC23: HF ETT female Calves | BD23: Jersey ETT Male Calves | BE23: Jersey ETT female Calves | BF23: Imported HF Male Calves | BG23: Imported HF female Calves | BH23: Imported Jersey Male Calves | BI23: Imported Jersey Cow female Calves | BJ23: Sexed Semon Cow Male Calves | BK23: Sexed Semon Cow Female Calves | BL23: Murrah Male Calves | BM23: Murrah Female Calves | BN23: Nili Ravi Male Calves | BO23: Nili Ravi Female Calves | BP23: HF Straws Used INAPH during month | BQ23: Jesey Straws Used INAPH during month | BR23: Cross Breed Straws Used INAPH during month | BS23: Sahiwal Straws Used INAPH during month | BT23: HF ETT Straws Used INAPH during month | BU23: Jersey ETT Straws Used INAPH during month | BV23: Imported HF Straws Used INAPH during month | BW23: Imported Jersey Straws Used INAPH during month | BX23: Sexed Straws Used INAPH during month | BY23: Murrah Straws Used INAPH during month | BZ23: Nili Ravi Straws Used INAPH during month | CA23: HF Straws Issued to AIW during Month | CB23: Jesey Straws Issued to AIW during Month | CC23: Cross Breed Straws Issued to AIW during Month | CD23: Sahiwal Straws Issued to AIW during Month | CE23: HF ETT Straws Issued to AIW during Month | CF23: Jersey ETT Straws Issued to AIW during Month | CG23: Imported HF Straws Issued to AIW during Month | CH23: Imported Jersey Straws Issued to AIW during Month | CI23: Sexed Straws Issued to AIW during Month | CJ23: Murrah Straws Issued to AIW during Month | CK23: Nili Ravi Straws Issued to AIW during Month | CL23: HF Straws Received During Month | CM23: Jesey Straws Received During Month | CN23: Cross Breed Straws Received During Month | CO23: Sahiwal Straws Received During Month | CP23: HF ETT Straws Received During Month | CQ23: Jersey ETT Straws Received During Month | CR23: Imported HF Straws Received During Month | CS23: Imported Jersey Straws Received During Month | CT23: Sexed Straws Received During Month | CU23: Murrah Straws Received During Month | CV23: Nili Ravi Straws Received During Month
A24: This Month | B24: =sumifs('Form responses'!AV2:AV53,'Form responses'!$C$2:$C53,">="&$E$2,'Form responses'!$C$2:$C53,"<="&$G$2,'Form responses'!$F$2:$F53,"=4") -> 0 | C24: =sumifs('Form responses'!AW2:AW53,'Form responses'!$C$2:$C53,">="&$E$2,'Form responses'!$C$2:$C53,"<="&$G$2,'Form responses'!$F$2:$F53,"=4") -> 0 | D24: =sumifs('Form responses'!AX2:AX53,'Form responses'!$C$2:$C53,">="&$E$2,'Form responses'!$C$2:$C53,"<="&$G$2,'Form responses'!$F$2:$F53,"=4") -> 0 | E24: =sumifs('Form responses'!AY2:AY53,'Form responses'!$C$2:$C53,">="&$E$2,'Form responses'!$C$2:$C53,"<="&$G$2,'Form responses'!$F$2:$F53,"=4") -> 0 | F24: =sumifs('Form responses'!AZ2:AZ53,'Form responses'!$C$2:$C53,">="&$E$2,'Form responses'!$C$2:$C53,"<="&$G$2,'Form responses'!$F$2:$F53,"=4") -> 0 | G24: =sumifs('Form responses'!BA2:BA53,'Form responses'!$C$2:$C53,">="&$E$2,'Form responses'!$C$2:$C53,"<="&$G$2,'Form responses'!$F$2:$F53,"=4") -> 0 | H24: =sumifs('Form responses'!BB2:BB53,'Form responses'!$C$2:$C53,">="&$E$2,'Form responses'!$C$2:$C53,"<="&$G$2,'Form responses'!$F$2:$F53,"=4") -> 0 | I24: =sumifs('Form responses'!BC2:BC53,'Form responses'!$C$2:$C53,">="&$E$2,'Form responses'!$C$2:$C53,"<="&$G$2,'Form responses'!$F$2:$F53,"=4") -> 0 | ... CV24: =sumifs('Form responses'!EP2:EP53,'Form responses'!$C$2:$C53,">="&$E$2,'Form responses'!$C$2:$C53,"<="&$G$2,'Form responses'!$F$2:$F53,"=4") -> 0
A25: This Year | B25: =sumifs('Form responses'!AV2:AV53,'Form responses'!$C$2:$C53,"<="&$G$2,'Form responses'!$C$2:$C53,">="&Date(YEAR(DATE(YEAR($G$2),MONTH($G$2)+(-3),1)),4,1),'Form responses'!$F$2:$F53,"=4") -> 0 | C25: =sumifs('Form responses'!AW2:AW53,'Form responses'!$C$2:$C53,"<="&$G$2,'Form responses'!$C$2:$C53,">="&Date(YEAR(DATE(YEAR($G$2),MONTH($G$2)+(-3),1)),4,1),'Form responses'!$F$2:$F53,"=4") -> 0 | D25: =sumifs('Form responses'!AX2:AX53,'Form responses'!$C$2:$C53,"<="&$G$2,'Form responses'!$C$2:$C53,">="&Date(YEAR(DATE(YEAR($G$2),MONTH($G$2)+(-3),1)),4,1),'Form responses'!$F$2:$F53,"=4") -> 0 | E25: =sumifs('Form responses'!AY2:AY53,'Form responses'!$C$2:$C53,"<="&$G$2,'Form responses'!$C$2:$C53,">="&Date(YEAR(DATE(YEAR($G$2),MONTH($G$2)+(-3),1)),4,1),'Form responses'!$F$2:$F53,"=4") -> 0 | F25: =sumifs('Form responses'!AZ2:AZ53,'Form responses'!$C$2:$C53,"<="&$G$2,'Form responses'!$C$2:$C53,">="&Date(YEAR(DATE(YEAR($G$2),MONTH($G$2)+(-3),1)),4,1),'Form responses'!$F$2:$F53,"=4") -> 0 | G25: =sumifs('Form responses'!BA2:BA53,'Form responses'!$C$2:$C53,"<="&$G$2,'Form responses'!$C$2:$C53,">="&Date(YEAR(DATE(YEAR($G$2),MONTH($G$2)+(-3),1)),4,1),'Form responses'!$F$2:$F53,"=4") -> 0 | H25: =sumifs('Form responses'!BB2:BB53,'Form responses'!$C$2:$C53,"<="&$G$2,'Form responses'!$C$2:$C53,">="&Date(YEAR(DATE(YEAR($G$2),MONTH($G$2)+(-3),1)),4,1),'Form responses'!$F$2:$F53,"=4") -> 0 | I25: =sumifs('Form responses'!BC2:BC53,'Form responses'!$C$2:$C53,"<="&$G$2,'Form responses'!$C$2:$C53,">="&Date(YEAR(DATE(YEAR($G$2),MONTH($G$2)+(-3),1)),4,1),'Form responses'!$F$2:$F53,"=4") -> 0 | ... CV25: =sumifs('Form responses'!EP2:EP53,'Form responses'!$C$2:$C53,"<="&$G$2,'Form responses'!$C$2:$C53,">="&Date(YEAR(DATE(YEAR($G$2),MONTH($G$2)+(-3),1)),4,1),'Form responses'!$F$2:$F53,"=4") -> 0
B28: Sum of | C28: =Reports!J1 -> Institute | E28: =Reports!$N$1 -> 44952 | F28: To | G28: =Reports!Q1 -> 44982
B29: NEW CASES EQUINE | C29: NEW CASES BOVINE | D29: NEW CASES OTHERS | E29: NEW CASES DOGS | F29: OLD CASES EQUINE | G29: OLD CASES BOVINE | H29: OLD CASES OTHERS | I29: OLD CASES DOGS | J29: TREATED IN CAMP EQUINE | K29: TREATED IN CAMP BOVINE | L29: TREATED IN CAMP OTHERS | M29: TREATED IN CAMP DOGS | N29: BOVINE CASTRATIONS | O29: OTHERS CASTRATIONS | P29: Number of Pregnancy Diagnosis (OTHER THEN FALLOWUP) | Q29: A.H. Certificate Small Animals | R29: A.H. Certificate Large Animals | S29: Post Mortem Small Animals | T29: Post Mortem Large Animals | U29: Post Mortem Vetro legal | V29: H.S. Vaccine Doses Received | W29: H.S. Vaccine Doses Received | X29: H.S. Vaccine Doses Used | Y29: FMD. Vaccine Doses Received | Z29: FMD. Vaccine Doses Used | AA29: FMD. Vaccine Animal Vaccinated | AB29: Black Quarter Doses Received | AC29: Black Quarter Doses Used | AD29: Black Quarter Animal Vaccinated | AE29: Brucellosis Vaccine Doses Received | AF29: Brucellosis Vaccine Doses Used | AG29: Brucellosis Vaccine Animal Vaccinated | AH29: Entero Toximia Vaccine Doses Received | AI29: Entero Toximia Vaccine Doses Used | AJ29: Entero Toximia Vaccine Animals Vaccinated | AK29: Theilaria Vaccine Doses Received | AL29: Theilaria Vaccine Doses Used | AM29: Theilaria Vaccine Animal Vaccinated | AN29: Rabies Vaccine Doses Received | AO29: Rabies Vaccine Doses Used | AP29: Rabies Vaccine Animal Vaccinated | AQ29: AI Done With HF Straws | AR29: AI Done With Jersey Straws | AS29: AI Done With Cross Breed Straws | AT29: AI Done With Sahiwal Straws | AU29: Cow Cover With HF Straws | AV29: Cow Cover With Jersey Straws | AW29: Cow Cover With Cross Breed Straws | AX29: Cow Cover With Sahiwal Straws | AY29: AI Done With HF ETT Straws | AZ29: AI Done With Jersey ETT Straws | BA29: AI Done With Imported HF Straws | BB29: AI Done With Imported Jersey Straws | BC29: Cow Cover With HF ETT Straws | BD29: Cow Cover With Jersey ETT Straws | BE29: Cow Cover With Imported HF Straws | BF29: Cow Cover With Imported Jersey Straws | BG29: AI Done With Sexed Straws | BH29: Cow Cover With Sexed Straws | BI29: AI Done With Murrah Straws | BJ29: AI Done With Nili-Ravi Straws | BK29: Buffalo Cover With Murrah Straws | BL29: Buffalo Cover With Nili-Ravi Straws | BM29: HF Cow Tested | BN29: HF Cow Tested and Found Postive | BO29: Jersey Cow Tested | BP29: Jersey Cow Tested and Found Postive | BQ29: Cross Breed Cow Tested | BR29: Cross Breed Cow Tested and Found Postive | BS29: Sahiwal Cow Tested | BT29: Sahiwal Cow Tested and Found Postive | BU29: HF ETT Cow Tested | BV29: HF ETT Cow Tested and Found Postive | BW29: Jessey ETT Cow Tested | BX29: Jessey ETT Cow Tested and Found Postive | BY29: Imported HF Cow Tested | BZ29: Imported HF Cow Tested and Found Postive | CA29: Imported Jersey Cow Tested | CB29: Imported Jersey Cow Tested and Found Postive | CC29: Sexed Semon Cows Tested | CD29: Sexed Semon Cows Found Postive | CE29: Murah Tested | CF29: Murah Tested and Found Postive | CG29: Nili Ravi Tested | CH29: Nili Tested and Found Postive | CI29: HF Male Calves | CJ29: HF female Calves | CK29: Jersey Male Calves | CL29: Jersey Cow female Calves | CM29: Cross Breed Male Calves | CN29: Cross Breed Cow female Calves | CO29: Sahiwal Male Calves | CP29: Sahiwal female Calves | CQ29: HF ETT Male Calves | CR29: HF ETT female Calves | CS29: Jersey ETT Male Calves | CT29: Jersey ETT female Calves | CU29: Imported HF Male Calves | CV29: Imported HF female Calves | CW29: Imported Jersey Male Calves | CX29: Imported Jersey Cow female Calves | CY29: Sexed Semon Cow Male Calves | CZ29: Sexed Semon Cow Female Calves | DA29: Murrah Male Calves | DB29: Murrah Female Calves | DC29: Nili Ravi Male Calves | DD29: Nili Ravi Female Calves | DE29: HF Straws Used INAPH during month | DF29: Jesey Straws Used INAPH during month | DG29: Cross Breed Straws Used INAPH during month | DH29: Sahiwal Straws Used INAPH during month | DI29: HF ETT Straws Used INAPH during month | DJ29: Jersey ETT Straws Used INAPH during month | DK29: Imported HF Straws Used INAPH during month | DL29: Imported Jersey Straws Used INAPH during month | DM29: Sexed Straws Used INAPH during month | DN29: Murrah Straws Used INAPH during month | DO29: Nili Ravi Straws Used INAPH during month | DP29: HF Straws Issued to AIW during Month | DQ29: Jesey Straws Issued to AIW during Month | DR29: Cross Breed Straws Issued to AIW during Month | DS29: Sahiwal Straws Issued to AIW during Month | DT29: HF ETT Straws Issued to AIW during Month | DU29: Jersey ETT Straws Issued to AIW during Month | DV29: Imported HF Straws Issued to AIW during Month | DW29: Imported Jersey Straws Issued to AIW during Month | DX29: Sexed Straws Issued to AIW during Month | DY29: Murrah Straws Issued to AIW during Month | DZ29: Nili Ravi Straws Issued to AIW during Month | EA29: HF Straws Received During Month | EB29: Jesey Straws Received During Month | EC29: Cross Breed Straws Received During Month | ED29: Sahiwal Straws Received During Month | EE29: HF ETT Straws Received During Month | EF29: Jersey ETT Straws Received During Month | EG29: Imported HF Straws Received During Month | EH29: Imported Jersey Straws Received During Month | EI29: Sexed Straws Received During Month | EJ29: Murrah Straws Received During Month | EK29: Nili Ravi Straws Received During Month
A30: This Month | B30: =sumifs('Form responses'!G2:G53,'Form responses'!$C$2:$C53,">="&$E$28,'Form responses'!$C$2:$C53,"<="&$G$28,'Form responses'!$D$2:$D53,$C$28) -> 0 | C30: =sumifs('Form responses'!H2:H53,'Form responses'!$C$2:$C53,">="&$E$28,'Form responses'!$C$2:$C53,"<="&$G$28,'Form responses'!$D$2:$D53,$C$28) -> 0 | D30: =sumifs('Form responses'!I2:I53,'Form responses'!$C$2:$C53,">="&$E$28,'Form responses'!$C$2:$C53,"<="&$G$28,'Form responses'!$D$2:$D53,$C$28) -> 0 | E30: =sumifs('Form responses'!J2:J53,'Form responses'!$C$2:$C53,">="&$E$28,'Form responses'!$C$2:$C53,"<="&$G$28,'Form responses'!$D$2:$D53,$C$28) -> 0 | F30: =sumifs('Form responses'!K2:K53,'Form responses'!$C$2:$C53,">="&$E$28,'Form responses'!$C$2:$C53,"<="&$G$28,'Form responses'!$D$2:$D53,$C$28) -> 0 | G30: =sumifs('Form responses'!L2:L53,'Form responses'!$C$2:$C53,">="&$E$28,'Form responses'!$C$2:$C53,"<="&$G$28,'Form responses'!$D$2:$D53,$C$28) -> 0 | H30: =sumifs('Form responses'!M2:M53,'Form responses'!$C$2:$C53,">="&$E$28,'Form responses'!$C$2:$C53,"<="&$G$28,'Form responses'!$D$2:$D53,$C$28) -> 0 | I30: =sumifs('Form responses'!N2:N53,'Form responses'!$C$2:$C53,">="&$E$28,'Form responses'!$C$2:$C53,"<="&$G$28,'Form responses'!$D$2:$D53,$C$28) -> 0 | ... AO30: =sumifs('Form responses'!AT2:AT53,'Form responses'!$C$2:$C53,">="&$E$28,'Form responses'!$C$2:$C53,"<="&$G$28,'Form responses'!$D$2:$D53,$C$28) -> 0 | AP30: 0 | AQ30: =sumifs('Form responses'!AV2:AV53,'Form responses'!$C$2:$C53,">="&$E$28,'Form responses'!$C$2:$C53,"<="&$G$28,'Form responses'!$D$2:$D53,$C$28) -> 0 | AR30: =sumifs('Form responses'!AW2:AW53,'Form responses'!$C$2:$C53,">="&$E$28,'Form responses'!$C$2:$C53,"<="&$G$28,'Form responses'!$D$2:$D53,$C$28) -> 0 | AS30: =sumifs('Form responses'!AX2:AX53,'Form responses'!$C$2:$C53,">="&$E$28,'Form responses'!$C$2:$C53,"<="&$G$28,'Form responses'!$D$2:$D53,$C$28) -> 0 | AT30: =sumifs('Form responses'!AY2:AY53,'Form responses'!$C$2:$C53,">="&$E$28,'Form responses'!$C$2:$C53,"<="&$G$28,'Form responses'!$D$2:$D53,$C$28) -> 0 | AU30: =sumifs('Form responses'!AZ2:AZ53,'Form responses'!$C$2:$C53,">="&$E$28,'Form responses'!$C$2:$C53,"<="&$G$28,'Form responses'!$D$2:$D53,$C$28) -> 0 | AV30: =sumifs('Form responses'!BA2:BA53,'Form responses'!$C$2:$C53,">="&$E$28,'Form responses'!$C$2:$C53,"<="&$G$28,'Form responses'!$D$2:$D53,$C$28) -> 0 | AW30: =sumifs('Form responses'!BB2:BB53,'Form responses'!$C$2:$C53,">="&$E$28,'Form responses'!$C$2:$C53,"<="&$G$28,'Form responses'!$D$2:$D53,$C$28) -> 0 | AX30: =sumifs('Form responses'!BC2:BC53,'Form responses'!$C$2:$C53,">="&$E$28,'Form responses'!$C$2:$C53,"<="&$G$28,'Form responses'!$D$2:$D53,$C$28) -> 0 | ... EK30: =sumifs('Form responses'!EP2:EP53,'Form responses'!$C$2:$C53,">="&$E$28,'Form responses'!$C$2:$C53,"<="&$G$28,'Form responses'!$D$2:$D53,$C$28) -> 0
A31: This Year | B31: =sumifs('Form responses'!G2:G53,'Form responses'!$C$2:$C53,"<="&$G$28,'Form responses'!$C$2:$C53,">="&Date(YEAR(DATE(YEAR($G$28),MONTH($G$28)+(-3),1)),4,1),'Form responses'!$D$2:$D53,$C$28) -> 0 | C31: =sumifs('Form responses'!H2:H53,'Form responses'!$C$2:$C53,"<="&$G$28,'Form responses'!$C$2:$C53,">="&Date(YEAR(DATE(YEAR($G$28),MONTH($G$28)+(-3),1)),4,1),'Form responses'!$D$2:$D53,$C$28) -> 0 | D31: =sumifs('Form responses'!I2:I53,'Form responses'!$C$2:$C53,"<="&$G$28,'Form responses'!$C$2:$C53,">="&Date(YEAR(DATE(YEAR($G$28),MONTH($G$28)+(-3),1)),4,1),'Form responses'!$D$2:$D53,$C$28) -> 0 | E31: =sumifs('Form responses'!J2:J53,'Form responses'!$C$2:$C53,"<="&$G$28,'Form responses'!$C$2:$C53,">="&Date(YEAR(DATE(YEAR($G$28),MONTH($G$28)+(-3),1)),4,1),'Form responses'!$D$2:$D53,$C$28) -> 0 | F31: =sumifs('Form responses'!K2:K53,'Form responses'!$C$2:$C53,"<="&$G$28,'Form responses'!$C$2:$C53,">="&Date(YEAR(DATE(YEAR($G$28),MONTH($G$28)+(-3),1)),4,1),'Form responses'!$D$2:$D53,$C$28) -> 0 | G31: =sumifs('Form responses'!L2:L53,'Form responses'!$C$2:$C53,"<="&$G$28,'Form responses'!$C$2:$C53,">="&Date(YEAR(DATE(YEAR($G$28),MONTH($G$28)+(-3),1)),4,1),'Form responses'!$D$2:$D53,$C$28) -> 0 | H31: =sumifs('Form responses'!M2:M53,'Form responses'!$C$2:$C53,"<="&$G$28,'Form responses'!$C$2:$C53,">="&Date(YEAR(DATE(YEAR($G$28),MONTH($G$28)+(-3),1)),4,1),'Form responses'!$D$2:$D53,$C$28) -> 0 | I31: =sumifs('Form responses'!N2:N53,'Form responses'!$C$2:$C53,"<="&$G$28,'Form responses'!$C$2:$C53,">="&Date(YEAR(DATE(YEAR($G$28),MONTH($G$28)+(-3),1)),4,1),'Form responses'!$D$2:$D53,$C$28) -> 0 | ... EK31: =sumifs('Form responses'!EP2:EP53,'Form responses'!$C$2:$C53,"<="&$G$28,'Form responses'!$C$2:$C53,">="&Date(YEAR(DATE(YEAR($G$28),MONTH($G$28)+(-3),1)),4,1),'Form responses'!$D$2:$D53,$C$28) -> 0
B33: Service Charges of this month
B34: OPD Case Fees | C34: OPD Case Dogs Fees | D34: Pregnency Diagnose Fee | E34: Castration Fee | F34: Health certificate Fee small animals | G34: Health certificate Fee Large animals | H34: Post Mortum Fee small animals | I34: Post Mortum Fee Large animals | J34: HS Vaccine fee | K34: FMD Vaccine Fee | L34: BQ Vaccine fee | M34: Brucellosis Vaccine Fee | N34: Theilaria Vaccine Fee | O34: Rabies Vaccine Fee | P34: ETV vaccine Fee | Q34: AI Cow Fee (Local semon) | R34: Ai Cow Fee (ETT Semon) | S34: AI Cow Fee (Imported Semon) | T34: AI Cow Fee (Sexed Semon) | U34: AI Fee Buffalow | V34: Faecal test Fee | W34: Blood Test Fee | X34: Urine Test Fee | Y34: Milk Test Fee | Z34: Post Mortum Fee Vetro legal
A35: This month | B35: =sumifs(fees!C$2:C53,fees!$B$2:$B53,">="&$E$28,fees!$B$2:$B53,"<="&$G$28) -> 10 | C35: =sumifs(fees!D$2:D53,fees!$B$2:$B53,">="&$E$28,fees!$B$2:$B53,"<="&$G$28) -> 50 | D35: =sumifs(fees!E$2:E53,fees!$B$2:$B53,">="&$E$28,fees!$B$2:$B53,"<="&$G$28) -> 25 | E35: =sumifs(fees!F$2:F53,fees!$B$2:$B53,">="&$E$28,fees!$B$2:$B53,"<="&$G$28) -> 50 | F35: =sumifs(fees!G$2:G53,fees!$B$2:$B53,">="&$E$28,fees!$B$2:$B53,"<="&$G$28) -> 50 | G35: =sumifs(fees!H$2:H53,fees!$B$2:$B53,">="&$E$28,fees!$B$2:$B53,"<="&$G$28) -> 100 | H35: =sumifs(fees!I$2:I53,fees!$B$2:$B53,">="&$E$28,fees!$B$2:$B53,"<="&$G$28) -> 20 | I35: =sumifs(fees!J$2:J53,fees!$B$2:$B53,">="&$E$28,fees!$B$2:$B53,"<="&$G$28) -> 100 | ... Z35: =sumifs(fees!AA$2:AA53,fees!$B$2:$B53,">="&$E$28,fees!$B$2:$B53,"<="&$G$28) -> 200
B37: Animals Cower 3 Month Ago
B38: Cow Cover With HF Straws | C38: Cow Cover With Jersey Straws | D38: Cow Cover With Cross Breed Straws | E38: Cow Cover With Sahiwal Straws | F38: Cow Cover With HF ETT Straws | G38: Cow Cover With Jersey ETT Straws | H38: Cow Cover With Imported HF Straws | I38: Cow Cover With Imported Jersey Straws | J38: Cow Cover With Sexed Straws | K38: Buffalo Cover With Murrah Straws | L38: Buffalo Cover With Nili-Ravi Straws
A39: That Month | B39: =sumifs('Form responses'!AZ2:AZ53,'Form responses'!$C$2:$C53,">="&edate($E$28,-3),'Form responses'!$C$2:$C53,"<="&edate($G$28,-3),'Form responses'!$D$2:$D53,$C$28) -> 0 | C39: =sumifs('Form responses'!BA2:BA53,'Form responses'!$C$2:$C53,">="&edate($E$28,-3),'Form responses'!$C$2:$C53,"<="&edate($G$28,-3),'Form responses'!$D$2:$D53,$C$28) -> 0 | D39: =sumifs('Form responses'!BB2:BB53,'Form responses'!$C$2:$C53,">="&edate($E$28,-3),'Form responses'!$C$2:$C53,"<="&edate($G$28,-3),'Form responses'!$D$2:$D53,$C$28) -> 0 | E39: =sumifs('Form responses'!BC2:BC53,'Form responses'!$C$2:$C53,">="&edate($E$28,-3),'Form responses'!$C$2:$C53,"<="&edate($G$28,-3),'Form responses'!$D$2:$D53,$C$28) -> 0 | F39: =sumifs('Form responses'!BH2:BH53,'Form responses'!$C$2:$C53,">="&edate($E$28,-3),'Form responses'!$C$2:$C53,"<="&edate($G$28,-3),'Form responses'!$D$2:$D53,$C$28) -> 0 | G39: =sumifs('Form responses'!BI2:BI53,'Form responses'!$C$2:$C53,">="&edate($E$28,-3),'Form responses'!$C$2:$C53,"<="&edate($G$28,-3),'Form responses'!$D$2:$D53,$C$28) -> 0 | H39: =sumifs('Form responses'!BJ2:BJ53,'Form responses'!$C$2:$C53,">="&edate($E$28,-3),'Form responses'!$C$2:$C53,"<="&edate($G$28,-3),'Form responses'!$D$2:$D53,$C$28) -> 0 | I39: =sumifs('Form responses'!BK2:BK53,'Form responses'!$C$2:$C53,">="&edate($E$28,-3),'Form responses'!$C$2:$C53,"<="&edate($G$28,-3),'Form responses'!$D$2:$D53,$C$28) -> 0 | J39: =sumifs('Form responses'!BM2:BM53,'Form responses'!$C$2:$C53,">="&edate($E$28,-3),'Form responses'!$C$2:$C53,"<="&edate($G$28,-3),'Form responses'!$D$2:$D53,$C$28) -> 0 | K39: =sumifs('Form responses'!BP2:BP53,'Form responses'!$C$2:$C53,">="&edate($E$28,-3),'Form responses'!$C$2:$C53,"<="&edate($G$28,-3),'Form responses'!$D$2:$D53,$C$28) -> 0 | L39: =sumifs('Form responses'!BQ2:BQ53,'Form responses'!$C$2:$C53,">="&edate($E$28,-3),'Form responses'!$C$2:$C53,"<="&edate($G$28,-3),'Form responses'!$D$2:$D53,$C$28) -> 0
B41: Cow Cover 9 Month and Buffalos Cover 10 Month Ago
B42: Cow Cover With HF Straws | C42: Cow Cover With Jersey Straws | D42: Cow Cover With Cross Breed Straws | E42: Cow Cover With Sahiwal Straws | F42: Cow Cover With HF ETT Straws | G42: Cow Cover With Jersey ETT Straws | H42: Cow Cover With Imported HF Straws | I42: Cow Cover With Imported Jersey Straws | J42: Cow Cover With Sexed Straws | K42: Buffalo Cover With Murrah Straws | L42: Buffalo Cover With Nili-Ravi Straws
A43: That Month | B43: =sumifs('Form responses'!AZ2:AZ53,'Form responses'!$C$2:$C53,">="&edate($E$28,-9),'Form responses'!$C$2:$C53,"<="&edate($G$28,-9),'Form responses'!$D$2:$D53,$C$28) -> 0 | C43: =sumifs('Form responses'!BA2:BA53,'Form responses'!$C$2:$C53,">="&edate($E$28,-9),'Form responses'!$C$2:$C53,"<="&edate($G$28,-9),'Form responses'!$D$2:$D53,$C$28) -> 0 | D43: =sumifs('Form responses'!BB2:BB53,'Form responses'!$C$2:$C53,">="&edate($E$28,-9),'Form responses'!$C$2:$C53,"<="&edate($G$28,-9),'Form responses'!$D$2:$D53,$C$28) -> 0 | E43: =sumifs('Form responses'!BC2:BC53,'Form responses'!$C$2:$C53,">="&edate($E$28,-9),'Form responses'!$C$2:$C53,"<="&edate($G$28,-9),'Form responses'!$D$2:$D53,$C$28) -> 0 | F43: =sumifs('Form responses'!BH2:BH53,'Form responses'!$C$2:$C53,">="&edate($E$28,-9),'Form responses'!$C$2:$C53,"<="&edate($G$28,-9),'Form responses'!$D$2:$D53,$C$28) -> 0 | G43: =sumifs('Form responses'!BI2:BI53,'Form responses'!$C$2:$C53,">="&edate($E$28,-9),'Form responses'!$C$2:$C53,"<="&edate($G$28,-9),'Form responses'!$D$2:$D53,$C$28) -> 0 | H43: =sumifs('Form responses'!BJ2:BJ53,'Form responses'!$C$2:$C53,">="&edate($E$28,-9),'Form responses'!$C$2:$C53,"<="&edate($G$28,-9),'Form responses'!$D$2:$D53,$C$28) -> 0 | I43: =sumifs('Form responses'!BK2:BK53,'Form responses'!$C$2:$C53,">="&edate($E$28,-9),'Form responses'!$C$2:$C53,"<="&edate($G$28,-9),'Form responses'!$D$2:$D53,$C$28) -> 0 | J43: =sumifs('Form responses'!BM2:BM53,'Form responses'!$C$2:$C53,">="&edate($E$28,-9),'Form responses'!$C$2:$C53,"<="&edate($G$28,-9),'Form responses'!$D$2:$D53,$C$28) -> 0 | K43: =sumifs('Form responses'!BP2:BP53,'Form responses'!$C$2:$C53,">="&edate($E$28,-10),'Form responses'!$C$2:$C53,"<="&edate($G$28,-10),'Form responses'!$D$2:$D53,$C$28) -> 0 | L43: =sumifs('Form responses'!BQ2:BQ53,'Form responses'!$C$2:$C53,">="&edate($E$28,-10),'Form responses'!$C$2:$C53,"<="&edate($G$28,-10),'Form responses'!$D$2:$D53,$C$28) -> 0
B45: Fecal Test of Institute
B46: Faecal test | C46: Fee | D46: Blood Test | E46: Fee | F46: Urine Test | G46: Fee | H46: Milk Test | I46: Fee | J46: Total fees
A47: This Month | B47: =sumifs('Form responses'!EQ2:EQ53,'Form responses'!$B$2:$B53,">="&$E$28,'Form responses'!$C$2:$C53,"<="&$G$28,'Form responses'!$D$2:$D53,$C$28) -> 0 | C47: =B47*$V$35 -> 0 | D47: =sumifs('Form responses'!ER2:ER53,'Form responses'!$B$2:$B53,">="&$E$28,'Form responses'!$C$2:$C53,"<="&$G$28,'Form responses'!$D$2:$D53,$C$28) -> 0 | E47: =D47*$W$35 -> 0 | F47: =sumifs('Form responses'!ES2:ES53,'Form responses'!$B$2:$B53,">="&$E$28,'Form responses'!$C$2:$C53,"<="&$G$28,'Form responses'!$D$2:$D53,$C$28) -> 0 | G47: =F47*$X$35 -> 0 | H47: =sumifs('Form responses'!ET2:ET53,'Form responses'!$B$2:$B53,">="&$E$28,'Form responses'!$C$2:$C53,"<="&$G$28,'Form responses'!$D$2:$D53,$C$28) -> 0 | I47: =H47*$Y$35 -> 0 | J47: =C47+E47+G47+I47 -> 0
A48: This Year | B48: =sumifs('Form responses'!EQ2:EQ53,'Form responses'!$B$2:$B53,">="&Date(YEAR(DATE(YEAR($G$28),MONTH($G$28)+(-3),1)),4,1),'Form responses'!$C$2:$C53,"<="&$G$28,'Form responses'!$D$2:$D53,$C$28) -> 0 | C48: =B48*$V$35 -> 0 | D48: =sumifs('Form responses'!ER2:ER53,'Form responses'!$B$2:$B53,">="&Date(YEAR(DATE(YEAR($G$28),MONTH($G$28)+(-3),1)),4,1),'Form responses'!$C$2:$C53,"<="&$G$28,'Form responses'!$D$2:$D53,$C$28) -> 0 | E48: =D48*$W$35 -> 0 | F48: =sumifs('Form responses'!ES2:ES53,'Form responses'!$B$2:$B53,">="&Date(YEAR(DATE(YEAR($G$28),MONTH($G$28)+(-3),1)),4,1),'Form responses'!$C$2:$C53,"<="&$G$28,'Form responses'!$D$2:$D53,$C$28) -> 0 | G48: =F48*$X$35 -> 0 | H48: =sumifs('Form responses'!ET2:ET53,'Form responses'!$B$2:$B53,">="&Date(YEAR(DATE(YEAR($G$28),MONTH($G$28)+(-3),1)),4,1),'Form responses'!$C$2:$C53,"<="&$G$28,'Form responses'!$D$2:$D53,$C$28) -> 0 | I48: =H48*$Y$35 -> 0 | J48: =C48+E48+G48+I48 -> 0

Sheet Credentials
A1: OrgIds | B1: Passwords | C1: Name of Institute | D1: Reporting Authority | E1: Name | F1: Designation | G1: Moble Nmber | H1: Email | I1: DOB | J1: Linked 1 | K1: Linked 2 | L1: Linked 3 | M1: Linked 4 | N1: Linked 5 | O1: Linked 6 | P1: Linked 7 | Q1: Login_Hash | R1: Is First Time | S1: Custom Dialog | T1: Report Submitted | U1: User Roles | V1: District | W1: Tesil
A2: test | B2: test | C2: Institute | D2: authority | E2: Name | F2: Designation | G2: 9417611720 | H2: arshpreetmalkana@gmail.com | Q2: aoaFUoKVOGTkMtk5xbwz | R2: 0 | S2: no_msg | T2: 0 | U2: 2 | V2: test | W2: test
A3: cvd9686 | B3: Ranj0086 | C3: CVD Gill Kalan | D3: Veterinary Officers Rampura Phul | E3: Ranjit Singh | F3: Veterinary Inspector | G3: 9417159086 | H3: ranjitbahiauid@gmail.com | Q3: EhkyZLPFZLjGSAU0ZNq6 | R3: 0 | S3: no_msg | T3: 0 | U3: 3 | V3: Bathinda | W3: rampura phul
A4: cvd5213 | B4: Pritpalkaur@1989 | C4: CVD Jai Singh Wala | D4: Vi CVD Jai Singh Wala | E4: Harjinder Singh | F4: Veterinary Inspector | G4: 8264328320 | H4: harjinders983@gmail.com | Q4: W3BmYs6tuqguboo0zpnU | R4: 0 | S4: no_msg | T4: 0 | U4: 3 | V4: Bathinda | W4: Bathinda
A5: cvd9401 | B5: Kanw6663 | C5: CVD Sivian | D5: Vi CVD Sivian | E5: Kanwaljit. Singh | F5: Veterinary Inspector | G5: 9876334873 | H5: maankanwaljit066@gmail.com | Q5: 6Y36x25nCdBiclThiIRX | R5: 0 | S5: no_msg | T5: 2 | U5: 3 | V5: Bathinda | W5: Bathinda
A6: cvd7072 | B6: Raji2530 | C6: CVD Aaklia Kalan | D6: Rajinder Singh | E6: Rajinder Singh | F6: Veterinary Inspector | G6: 9855917155 | H6: rajinderchaina87@gmail.com | Q6: UKzp7ND5xZ8NuT3A8OQS | R6: 1 | S6: no_msg | T6: 0 | U6: 3 | V6: Bathinda | W6: Bathinda
A7: cvd1937 | B7: Raji3820 | C7: CVD Aklia Kalan | D7: CVD Aklia Kalan | E7: Rajinder Singh | F7: Veterinary Inspector | G7: 9855917155 | H7: rajinderchaina29@gmail.com | R7: 1 | S7: no_msg | T7: 0 | U7: 3 | V7: Bathinda | W7: Bathinda
A8: cvd1337 | B8: MONI4724 | C8: CVD Bahoyatri | D8: Vo Teona | E8: Moninder Sharma | F8: Veterinary Inspector | G8: 8054051144 | H8: sharmamoninder472@gmail.com | Q8: U03YbUWTMUWcVgXmZcWT | R8: 1 | S8: no_msg | T8: 0 | U8: 3 | V8: Bathinda | W8: Bathinda
A9: cvd9851 | B9: Hard5965 | C9: CVD Bhagu | D9: V O Kotsmir | E9: Hardeep Singh | F9: Veterinary Inspector | G9: 9463268157 | H9: hschgiana@gmail.com | Q9: PtahFAk3eMo2F2BIbXMu | R9: 1 | S9: no_msg | T9: 0 | U9: 3 | V9: Bathinda | W9: Bathinda
A10: cvd8338 | B10: Nare4521 | C10: CVD Bhokhra | D10: Veterinary Officer Nahian Wala | E10: Naresh Kumar | F10: Veterinary Inspector | G10: 9814642975 | H10: nksharmaomx@gmail.com | Q10: 9W745lmiAHcU5fTz4H0u | R10: 1 | S10: no_msg | T10: 0 | U10: 3 | V10: Bathinda | W10: Bathinda
A11: cvd5815 | B11: Nav8146 | C11: CVD Bhucho Kalan | D11: V.I.Navdeep Singh | E11: Navdeep Singh | F11: Veterinary Inspector | G11: 8146244530 | H11: veterinaryinspector1094@gmail.com | Q11: MvLSMMzi1lrTBGYQKdOR | R11: 0 | S11: no_msg | T11: 0 | U11: 3 | V11: Bathinda | W11: Bathinda
A12: cvd5433 | B12: GURP9229 | C12: CVD Multania | D12: Vo Teona | E12: Gurpreet Singh | F12: Veterinary Inspector | G12: 9872205826 | H12: bawa.gurpreetsingh@yahoo.in | R12: 1 | S12: no_msg | T12: 0 | U12: 3 | V12: Bathinda | W12: Bathinda
A13: cvd7408 | B13: MALK2055 | C13: CVD Cvdbirbehman | D13: CVD Bir Behman | E13: Malkeet Singh | F13: Veterinary Inspector | G13: 9855518770 | H13: malkeet25@gmail.com | Q13: wMDKjvn0pUyRQMUB8tGG | R13: 0 | S13: no_msg | T13: 2 | U13: 3 | V13: Bathinda | W13: Bathinda
A14: cvd2115 | B14: HARW6833 | C14: CVD Gurusar Sainewala | D14: Vo CVH Naruana | E14: Harwinder Singh | F14: Veterinary Inspector | G14: 9877136065 | H14: hsgill90031@gmail.com | Q14: ie0BVjRNOHVqyj8Rtv6R | R14: 1 | S14: no_msg | T14: 0 | U14: 3 | V14: Bathinda | W14: Bathinda
A15: cvd7434 | B15: Arsh3287 | C15: CVD Jangirana | D15: Vi Arshdeep Kaur | E15: Arshdeep Kaur | F15: Veterinary Inspector | G15: 8699649180 | H15: arshdeepji189@gmail.com | Q15: UYihdisYqcpjcGHNMxNb | R15: 1 | S15: no_msg | T15: 0 | U15: 3 | V15: Bathinda | W15: Bathinda
A16: cvd6373 | B16: balj1584 | C16: CVD Jhumba | D16: Vo Jhumba | E16: Baljinder Singh | F16: Veterinary Officer | G16: 9417380115 | H16: mindi67521@gmail.com | R16: 1 | S16: no_msg | T16: 0 | U16: 3 | V16: Bathinda | W16: Bathinda
A17: cvd1837 | B17: 5416 | C17: CVD Khialiwala | D17: Vo Jandanwala | E17: Barinderjit Sodhi | F17: Veterinary Inspector | G17: 9417326027 | H17: noordaisy@gmail.com | Q17: NELJcexTAh67SLGHCsCY | R17: 0 | S17: no_msg | T17: 2 | U17: 3 | V17: Bathinda | W17: Bathinda
A18: cvd5184 | B18: Gurbant@94 | C18: CVD Kothe Chet Singh | D18: Gurbant Singh | E18: Gurbant Singh | F18: Veterinary Inspector | G18: 9463425764 | H18: 9463425764g@gmail.com | Q18: Yny2Bwxp15LRmZinFL0X | R18: 0 | S18: no_msg | T18: 2 | U18: 3 | V18: Bathinda | W18: Bathinda
A19: cvd2107 | B19: Gaga8184 | C19: CVD Kothe Natha Singh Wala | D19: Vi Gagandeep Kaur | E19: Gagandeep Kaur | F19: Veterinary Inspector | G19: 6239601616 | H19: gagandeep81961@gmail.com | Q19: 2F7LCZsUmfYXhQePMyuA | R19: 1 | S19: no_msg | T19: 2 | U19: 3 | V19: Bathinda | W19: Bathinda
A20: cvd5877 | B20: Gurk9979 | C20: CVD Loolbai | D20: Dr. Devraj | E20: Gurkirtan Singh | F20: Veterinary Inspector | G20: 9463967789 | H20: gurkirtankang12@gmail.com | R20: 1 | S20: no_msg | T20: 0 | U20: 3 | V20: Bathinda | W20: Bathinda
A21: cvd6235 | B21: 1234 | C21: CVD Multania | D21: Vi Multania | E21: Gurpreet Singh | F21: Veterinary Inspector | G21: 9872205826 | H21: bawa.gurpreetsingh@yahoo.in | Q21: CQgZz4IyZlaJGDhxvIGE | R21: 0 | S21: no_msg | T21: 0 | U21: 3 | V21: Bathinda | W21: Bathinda
A22: cvd8725 | B22: JAI 2526 | C22: CVD Nandgarh | D22: Vo Ghudda | E22: Jai Prakash | F22: Veterinary Inspector | G22: 9417562733 | H22: mishrajai81@gmail.com | R22: 1 | S22: no_msg | T22: 0 | U22: 3 | V22: Bathinda | W22: Bathinda
A23: cvd3766 | B23: jai2301 | C23: CVD Nandgarh | D23: Vi Nandgarh | E23: Jai Prakash | F23: Veterinary Inspector | G23: 9417562733 | H23: mishrajai81@gmail.com | Q23: RElj4FS1sR9RlpZhEJuD | R23: 0 | S23: no_msg | T23: 0 | U23: 3 | V23: Bathinda | W23: Bathinda
A24: cvd4217 | B24: Gurj5472 | C24: CVD Poohli | D24: Vo Sema | E24: Gurjit Singh | F24: Veterinary Inspector | G24: 7888790564 | H24: gurjitpoohli991@gmail.com | Q24: v8vWSccwz6v4uVOcSuQz | R24: 1 | S24: no_msg | T24: 0 | U24: 3 | V24: Bathinda | W24: Bathinda
A25: cvh7295 | B25: Jasw8045 | C25: CVH Blahar Vinjhu | D25: Vi Blahar Vinjhu | E25: Jaswinder Singh Dhillon | F25: Veterinary Inspector | G25: 9417139492 | H25: jsdhillon045@gmail.com | Q25: Cr4agH01N9JWpU2V5sym | R25: 1 | S25: no_msg | T25: 0 | U25: 2 | V25: Bathinda | W25: Bathinda
A26: cvh6625 | B26: SUKH5567 | C26: CVH CVH Pathrala | D26: Vo Pathrala | E26: Sukhveer Singh | F26: Veterinary Inspector | G26: 9877579159 | H26: singhsukhveer95@gmail.com | R26: 1 | S26: no_msg | T26: 0 | U26: 2 | V26: Bathinda | W26: Bathinda
A27: cvh3522 | B27: GURP5172 | C27: CVH CVH Poohla | D27: Vo Poohla | E27: Gurpreet Singh | F27: Veterinary Inspector | G27: 9464253393 | H27: gssvet@gmail.com | Q27: dmjJY6djpMpqo6xVvC8C | R27: 1 | S27: no_msg | T27: 0 | U27: 2 | V27: Bathinda | W27: Bathinda
A28: cvh9380 | B28: 7576harpreet | C28: CVH Ghudda | D28: Dr. Devraj | E28: Harpreet Singh | F28: Veterinary Inspector | G28: 9815991636 | H28: harpreetsra75761@gmail.com | Q28: 0MSybrqZjW3M5SoQcJta | R28: 0 | S28: no_msg | T28: 0 | U28: 2 | V28: Bathinda | W28: Bathinda
A29: cvh5758 | B29: Hn7888755490@ | C29: CVH Kot Fatta | D29: Svo Bathinda | E29: Dr Harwinder Singh | F29: Veterinary Officer | G29: 9464302899 | H29: harryvet05@gmail.com | Q29: to5F1DJkYXC94VjnvVTp | R29: 0 | S29: no_msg | T29: 0 | U29: 1 | V29: Bathinda | W29: Bathinda
A30: cvh7137 | B30: DrG2836 | C30: CVH Kotshamir | D30: Vo Kotshamir | E30: Dr Gurminder Singh | F30: Veterinary Officer | G30: 9653120566 | H30: sidhusukhmander762@gmail.com | Q30: DDy2PwDvhP72RvwSRQlJ | R30: 1 | S30: no_msg | T30: 0 | U30: 1 | V30: Bathinda | W30: Bathinda
A31: cvh3276 | B31: HARI7082 | C31: CVH Lehra Mohabat | D31: Vo Lehra Mohabat | E31: Harinder Kumar | F31: Veterinary Inspector | G31: 9417310109 | H31: garghk1444@gmail.com | Q31: 3NU2RLpfYvEqfNWx2psg | R31: 0 | S31: no_msg | T31: 2 | U31: 2 | V31: Bathinda | W31: Bathinda
A32: cvh1594 | B32: pawa7815 | C32: CVH Pathrala | D32: Pawandeep | E32: Pawandeep Singh | F32: Veterinary Officer | G32: 9915395506 | H32: singhsukhveer95@gmail.com | R32: 1 | S32: no_msg | T32: 0 | U32: 2 | V32: Bathinda | W32: Bathinda
A33: cvh4868 | B33: bhuchomandi@123 | C33: CVH Bhucho Mandi | D33: Vo Bhucho Mandi | E33: Jaspreet Singh | F33: Veterinary Inspector | G33: 9041020508 | H33: jaspreetsingh7961@gmail.com | Q33: jw38UMlAGa9fAFDecLCi | R33: 0 | S33: no_msg | T33: 0 | U33: 2 | V33: Bathinda | W33: Bathinda
A34: cvh7602 | B34: Durgesh@123 | C34: CVH Naruana | D34: Svo Bathinda | E34: Dr. Durgesh Nandini | F34: Veterinary Officer | G34: 9855231112 | H34: vetdr.nandini@gmail.com | Q34: duWZJIpTM7cbuMg091Gt | R34: 0 | S34: no_msg | T34: 2 | U34: 2 | V34: Bathinda | W34: Bathinda
A35: cvd7648 | B35: vig8032 | C35: CVD V.I.Cvd Gillpatti | D35: V.O. Neia Wala | E35: Vi Gurpal Singh | F35: Veterinary Inspector | G35: 9915162720 | H35: gurpal000111@gmail.com | R35: 1 | S35: no_msg | T35: 0 | U35: 3 | V35: Bathinda | W35: Bathinda

Sheet Reports
G1: Monthly Report of | J1: Institute | M1: From | N1: 44952 | P1: To | Q1: 44982
B3: NEW CASES TREATED | F3: OLD CASES Treated | J3: Case Treated In Camps/Gaushala | N3: Total Cases Treated | R3: Castrations | T3: PD | U3: A.H.CERTIFICATE | W3: POST MORT.
A4: Species | B4: E | C4: B | D4: O | E4: PET | F4: E | G4: B | H4: O | I4: PET | J4: E | K4: B | L4: O | M4: PET | N4: E | O4: B | P4: O | Q4: PET | R4: B | S4: O | T4: NO | U4: small | V4: Large | W4: small | X4: Large | Y4: Vetro Legal
A5: During the Month | B5: =Sum!B30 -> 0 | C5: =Sum!C30 -> 0 | D5: =Sum!D30 -> 0 | E5: =Sum!E30 -> 0 | F5: =Sum!F30 -> 0 | G5: =Sum!G30 -> 0 | H5: =Sum!H30 -> 0 | I5: =Sum!I30 -> 0 | ... M5: =Sum!M30 -> 0 | N5: =B5+F5+J5 -> 0 | O5: =C5+G5+K5 -> 0 | P5: =D5+H5+L5 -> 0 | Q5: =E5+I5+M5 -> 0 | R5: =Sum!N30 -> 0 | S5: =Sum!O30 -> 0 | T5: =Sum!P30 -> 0 | U5: =Sum!Q30 -> 0 | V5: =Sum!R30 -> 0 | W5: =Sum!S30 -> 0 | X5: =Sum!T30 -> 0 | Y5: =Sum!U30 -> 0
A6: Progressive Total-> | B6: =Sum!B31 -> 0 | C6: =Sum!C31 -> 0 | D6: =Sum!D31 -> 0 | E6: =Sum!E31 -> 0 | F6: =Sum!F31 -> 0 | G6: =Sum!G31 -> 0 | H6: =Sum!H31 -> 0 | I6: =Sum!I31 -> 0 | ... M6: =Sum!M31 -> 0 | N6: =B6+F6+J6 -> 0 | O6: =C6+G6+K6 -> 0 | P6: =D6+H6+L6 -> 0 | Q6: =E6+I6+M6 -> 0 | R6: =Sum!N31 -> 0 | S6: =Sum!O31 -> 0 | T6: =Sum!P31 -> 0 | U6: =Sum!Q31 -> 0 | V6: =Sum!R31 -> 0 | W6: =Sum!S31 -> 0 | X6: =Sum!T31 -> 0
B8: VACCINATION REPORT
A9: VACCINE | B9: HS | E9: FMD | H9: BQ | K9: Brucellosis | N9: ETV | Q9: Theilaria | T9: Goat Pox
B10: DOSES Received | C10: DOSES Used | D10: No.of Animals Vaccinated | E10: DOSES Received | F10: DOSES Used | G10: No.of Animals Vaccinated | H10: DOSES Received | I10: DOSES Used | J10: No.of Animals Vaccinated | K10: DOSES Received | L10: DOSES Used | M10: No.of Animals Vaccinated | N10: DOSES Received | O10: DOSES Used | P10: No.of Animals Vaccinated | Q10: DOSES Received | R10: DOSES Used | S10: No.of Animals Vaccinated | T10: DOSES Received | U10: DOSES Used | V10: No.of Animals Vaccinated
A11: During the Month | B11: =Sum!V30 -> 0 | C11: =Sum!W30 -> 0 | D11: =Sum!X30 -> 0 | E11: =Sum!Y30 -> 0 | F11: =Sum!Z30 -> 0 | G11: =Sum!AA30 -> 0 | H11: =Sum!AB30 -> 0 | I11: =Sum!AC30 -> 0 | ... V11: =Sum!AP30 -> 0
A12: This Year | B12: =Sum!V31 -> 0 | C12: =Sum!W31 -> 0 | D12: =Sum!X31 -> 0 | E12: =Sum!Y31 -> 0 | F12: =Sum!Z31 -> 0 | G12: =Sum!AA31 -> 0 | H12: =Sum!AB31 -> 0 | I12: =Sum!AC31 -> 0 | ... V12: =Sum!AP31 -> 0
A13: Balane vaccine | B13: =sumifs('Form responses'!AA2:AA76, 'Form responses'!$C$2:$C76, "<="&Date(YEAR(DATE(YEAR($N$1),MONTH($N$1)+(-3),1)),4,1), 'Form responses'!$D$2:$D76,$J$1)-(sumifs('Form responses'!AB2:AB76, 'Form responses'!$C$2:$C76, "<="&Date(YEAR(DATE(YEAR($N$1),MONTH($N$1)+(-3),1)),4,1), 'Form responses'!$D$2:$D76,$J$1))+Sum!V31-Sum!W31 -> 0 | E13: =sumifs('Form responses'!AD2:AD76, 'Form responses'!$C$2:$C76, "<="&Date(YEAR(DATE(YEAR($N$1),MONTH($N$1)+(-3),1)),4,1), 'Form responses'!$D$2:$D76,$J$1)-(sumifs('Form responses'!AE2:AE76, 'Form responses'!$C$2:$C76, "<="&Date(YEAR(DATE(YEAR($N$1),MONTH($N$1)+(-3),1)),4,1), 'Form responses'!$D$2:$D76,$J$1))+Sum!Y31-Sum!Z31 -> 0 | H13: =sumifs('Form responses'!AG2:AG76, 'Form responses'!$C$2:$C76, "<="&Date(YEAR(DATE(YEAR($N$1),MONTH($N$1)+(-3),1)),4,1), 'Form responses'!$D$2:$D76,$J$1)-(sumifs('Form responses'!AH2:AH76, 'Form responses'!$C$2:$C76, "<="&Date(YEAR(DATE(YEAR($N$1),MONTH($N$1)+(-3),1)),4,1), 'Form responses'!$D$2:$D76,$J$1))+Sum!AB31-Sum!AC31 -> 0 | K13: =sumifs('Form responses'!AJ2:AJ76, 'Form responses'!$C$2:$C76, "<="&Date(YEAR(DATE(YEAR($N$1),MONTH($N$1)+(-3),1)),4,1), 'Form responses'!$D$2:$D76,$J$1)-(sumifs('Form responses'!AK2:AK76, 'Form responses'!$C$2:$C76, "<="&Date(YEAR(DATE(YEAR($N$1),MONTH($N$1)+(-3),1)),4,1), 'Form responses'!$D$2:$D76,$J$1))+Sum!AE31-Sum!AF31 -> 0 | N13: =sumifs('Form responses'!AM2:AM76, 'Form responses'!$C$2:$C76, "<="&Date(YEAR(DATE(YEAR($N$1),MONTH($N$1)+(-3),1)),4,1), 'Form responses'!$D$2:$D76,$J$1)-(sumifs('Form responses'!AN2:AN76, 'Form responses'!$C$2:$C76, "<="&Date(YEAR(DATE(YEAR($N$1),MONTH($N$1)+(-3),1)),4,1), 'Form responses'!$D$2:$D76,$J$1))+Sum!AH31-Sum!AI31 -> 0 | Q13: =sumifs('Form responses'!AP2:AP76, 'Form responses'!$C$2:$C76, "<="&Date(YEAR(DATE(YEAR($N$1),MONTH($N$1)+(-3),1)),4,1), 'Form responses'!$D$2:$D76,$J$1)-(sumifs('Form responses'!AQ2:AQ76, 'Form responses'!$C$2:$C76, "<="&Date(YEAR(DATE(YEAR($N$1),MONTH($N$1)+(-3),1)),4,1), 'Form responses'!$D$2:$D76,$J$1))+Sum!AK31-Sum!AL31 -> 0 | T13: =sumifs('Form responses'!AS2:AS76, 'Form responses'!$C$2:$C76, "<="&Date(YEAR(DATE(YEAR($N$1),MONTH($N$1)+(-3),1)),4,1), 'Form responses'!$D$2:$D76,$J$1)-(sumifs('Form responses'!AT2:AT76, 'Form responses'!$C$2:$C76, "<="&Date(YEAR(DATE(YEAR($N$1),MONTH($N$1)+(-3),1)),4,1), 'Form responses'!$D$2:$D76,$J$1))+Sum!AN31-Sum!AO31 -> 0
B14: A.I. WITH FROZEN SEMEN IN COWS
B15: HF | C15: JR | D15: CB | E15: SW | F15: HF cover | G15: JR Cover | H15: CB cover | I15: SW Cover | J15: AI ETT HF | K15: AI ETT JR | L15: AI Imp HF | M15: AI Imp JR | N15: Cover ETT HF | O15: Cover ETT JR | P15: Cover Imp HF | Q15: Cover Imp JR | R15: A.I. sexed | S15: Cover Sexed | T15: Total AI | U15: Total covered
A16: During the Month | B16: =Sum!AQ30 -> 0 | C16: =Sum!AR30 -> 0 | D16: =Sum!AS30 -> 0 | E16: =Sum!AT30 -> 0 | F16: =Sum!AU30 -> 0 | G16: =Sum!AV30 -> 0 | H16: =Sum!AW30 -> 0 | I16: =Sum!AX30 -> 0 | ... S16: =Sum!BH30 -> 0 | T16: =B16+C16+D16+E16+J16+K16+L16+M16+R16 -> 0 | U16: =F16+G16+H16+I16+N16+O16+P16+Q16+S16 -> 0
A17: Progressive Total | B17: =Sum!AQ31 -> 0 | C17: =Sum!AR31 -> 0 | D17: =Sum!AS31 -> 0 | E17: =Sum!AT31 -> 0 | F17: =Sum!AU31 -> 0 | G17: =Sum!AV31 -> 0 | H17: =Sum!AW31 -> 0 | I17: =Sum!AX31 -> 0 | ... S17: =Sum!BH31 -> 0 | T17: =B17+C17+D17+E17+J17+K17+L17+M17+R17 -> 0 | U17: =F17+G17+H17+I17+N17+O17+P17+Q17+S17 -> 0
B19: Pregnancy Diagnosis of AI in Cows
B20: HF | D20: Jersy | F20: Cross Breed | H20: Sahiwal | J20: HF ETT | L20: Jersey ETT | N20: Imported HF | P20: Imported Jersey | R20: Sexed
B21: TESTED | C21: +ve | D21: TESTED | E21: +ve | F21: TESTED | G21: +ve | H21: TESTED | I21: +ve | J21: TESTED | K21: +ve | L21: TESTED | M21: +ve | N21: TESTED | O21: +ve | P21: TESTED | Q21: +ve | R21: TESTED | S21: +ve
A22: Covered 3 Months ago | B22: =Sum!B39 -> 0 | D22: =Sum!C39 -> 0 | F22: =Sum!D39 -> 0 | H22: =Sum!E39 -> 0 | J22: =Sum!F39 -> 0 | L22: =Sum!G39 -> 0 | N22: =Sum!H39 -> 0 | P22: =Sum!I39 -> 0 | R22: =Sum!J39 -> 0
A23: During the Month | B23: =Sum!BM30 -> 0 | C23: =Sum!BN30 -> 0 | D23: =Sum!BO30 -> 0 | E23: =Sum!BP30 -> 0 | F23: =Sum!BQ30 -> 0 | G23: =Sum!BR30 -> 0 | H23: =Sum!BS30 -> 0 | I23: =Sum!BT30 -> 0 | ... S23: =Sum!CD30 -> 0
