Workbook

Sheet Cluster Responses
A1: Timestamp | B1: Date | C1: Name Of Cluster | D1: Transaction Type | E1: Recieving Institute | F1: HF straw | G1: Jersey Straw | H1: Cross Bred Straw | I1: Sahiwal Straw | J1: HF ETT Straw | K1: Jersey ETT Straw | L1: HF Sexed Straw | M1: Jersey Sexed Straw | N1: CB Sexed Straw | O1: Sahiwal Sexed Straw | P1: Murrah Straws | Q1: Nilli Ravi Straw | R1: Murrah Sexed Straw | S1: Nili-ravi Sexed Straw | T1: Other 1 | U1: Other 1
A2: 45032.517 | B2: 45016 | C2: CVH Talwandi Sabo | D2: Recieved | F2: 25 | H2: 30 | J2: 66 | L2: 30 | P2: 320 | R2: 40
A3: 45032.518 | B3: 45017 | C3: CVH Talwandi Sabo | D3: Issued | E3: CVD Teona Pujarian | F3: 5 | J3: 15 | P3: 15
A4: 45032.518 | B4: 45017 | C4: CVH Talwandi Sabo | D4: Issued | E4: CVH Talwandi Sabo | H4: 5 | P4: 5
A5: 45032.519 | B5: 45032 | C5: CVH Talwandi Sabo | D5: Issued | E5: CVD Chathewala | H5: 5 | J5: 30 | L5: 4 | P5: 15 | R5: 1
A6: 45032.522 | B6: 45017 | C6: CVH Talwandi Sabo | D6: Issued | E6: CVH Singo | J6: 15 | P6: 15
A7: 45032.523 | B7: 45019 | C7: CVH Talwandi Sabo | D7: Issued | E7: CVD Teona Pujarian | J7: 15
A8: 45032.523 | B8: 45021 | C8: CVH Talwandi Sabo | D8: Issued | E8: CVD Jaga Ram Tirath | P8: 30
A9: 45032.524 | B9: 45022 | C9: CVH Talwandi Sabo | D9: Issued | E9: CVH Natheha | P9: 30
A10: 45032.524 | B10: 45022 | C10: CVH Talwandi Sabo | D10: Issued | E10: CVD Burj Sema | F10: 5 | P10: 15 | R10: 10
A11: 45032.525 | B11: 45028 | C11: CVH Talwandi Sabo | D11: Recieved | F11: 15 | H11: 15
A12: 45032.525 | B12: 45032 | C12: CVH Talwandi Sabo | D12: Issued | E12: CVD Nangla | H12: 5
A13: 45032.526 | B13: 45028 | C13: CVH Talwandi Sabo | D13: Issued | E13: CVH Shekhpura | F13: 5 | P13: 30
A14: 45032.526 | B14: 45029 | C14: CVH Talwandi Sabo | D14: Issued | E14: CVD Kalalwala | F14: 5
A15: 45032.526 | B15: 45029 | C15: CVH Talwandi Sabo | D15: Issued | E15: CVD Rayia | F15: 5 | P15: 15
A16: 45032.527 | B16: 45031 | C16: CVH Talwandi Sabo | D16: Issued | E16: CVD Chathewala | H16: 15 | P16: 30
A17: 45032.527 | B17: 45031 | C17: CVH Talwandi Sabo | D17: Issued | E17: CVH Talwandi Sabo | F17: 5 | H17: 5
A18: 45032.542 | B18: 45029 | C18: CVH Talwandi Sabo | D18: Issued | E18: CVD Burj Sema
A19: 45032.853 | B19: 45031 | C19: CVH Talwandi Sabo | D19: Issued | E19: CVD Nangla | P19: 15
A20: 45034.661 | B20: 45034 | C20: CVH Talwandi Sabo | D20: Issued | E20: CVD Chathewala | L20: 10
A21: 45036.391 | B21: 45036 | C21: CVH Talwandi Sabo | D21: Issued | E21: CVH Talwandi Sabo | F21: 5 | H21: 10
A22: 45037.554 | B22: 45037 | C22: CVH Talwandi Sabo | D22: Issued | E22: CVH Talwandi Sabo | P22: 15
A23: 45045.368 | B23: 45040 | C23: CVH Talwandi Sabo | D23: Issued | E23: CVH Bhagiwander | P23: 15
A24: 45045.369 | B24: 45044 | C24: CVH Talwandi Sabo | D24: Recieved | L24: 30 | P24: 240 | R24: 30
A25: 45045.369 | B25: 45044 | C25: CVH Talwandi Sabo | D25: Issued | E25: CVH Talwandi Sabo | P25: 15
A26: 45045.56 | B26: 45045 | C26: CVH Talwandi Sabo | D26: Issued | E26: CVD Chathewala | F26: 5 | P26: 15
A27: 45045.565 | B27: 45045 | C27: CVH Talwandi Sabo | D27: Issued | E27: CVD Rayia | P27: 45
A28: 45048.37 | B28: 45048 | C28: CVH Talwandi Sabo | D28: Issued | E28: CVD Burj Sema | P28: 15
A29: 45048.484 | B29: 45048 | C29: CVH Talwandi Sabo | D29: Issued | E29: CVD Teona Pujarian | L29: 10 | P29: 30
A30: 45048.484 | B30: 45048 | C30: CVH Talwandi Sabo | D30: Issued | E30: CVD Nangla | P30: 15
A31: 45055.469 | B31: 45050 | C31: CVH Talwandi Sabo | D31: Issued | E31: CVH Natheha | P31: 30
A32: 45055.469 | B32: 45055 | C32: CVH Talwandi Sabo | D32: Issued | E32: CVH Bhagiwander | P32: 15
A33: 45055.55 | B33: 45055 | C33: CVH Talwandi Sabo | D33: Issued | E33: CVH Singo | P33: 15
A34: 45063.727 | B34: 45063 | C34: CVH Talwandi Sabo | D34: Issued | E34: CVD Nangla | P34: 15
A35: 45072.551 | B35: 45071 | C35: CVH Talwandi Sabo | D35: Issued | E35: CVD Rayia | P35: 0
A36: 45072.551 | B36: 45072 | C36: CVH Talwandi Sabo | D36: Recieved | P36: 105
A37: 45073.366 | B37: 45073 | C37: CVH Talwandi Sabo | D37: Issued | E37: CVD Chathewala | P37: 15
A38: 45073.366 | B38: 45073 | C38: CVH Talwandi Sabo | D38: Issued | E38: CVD Kalalwala | P38: 30
A39: 45076.473 | B39: 45076 | C39: CVH Talwandi Sabo | D39: Issued | E39: CVH Shekhpura | L39: 10 | P39: 45 | R39: 10
A40: 45076.474 | B40: 45076 | C40: CVH Talwandi Sabo | D40: Issued | E40: CVH Natheha | P40: 30
...

Sheet Credentials
A1: OrgIds | B1: Paassword | C1: Name of Institute | D1: Reporting Authority | E1: Name | F1: Designation | G1: Moble Nmber | H1: Email | I1: DOB | J1: Linked 1 | K1: Linked 2 | L1: Linked 3 | M1: Linked 4 | N1: Linked 5 | O1: Linked 6 | P1: Linked 7 | Q1: Login_Hash | R1: Is First Time | S1: Custom Dialog | T1: Report Submitted | U1: User Roles | V1: District | W1: Tesil | X1: is Semon Bank Available? | Y1: Cluster Attached | AA1: no_msg
A2: test | B2: test | C2: Talwandi Sabo | D2: Deputy Director Animal Husbandry Bathinda | E2: Dr. Harshit | F2: Senior Veterinary Officer | G2: 9417575128 | H2: kssidhu1@gmail.com | Q2: WjC1FerFKdXThlfcov39 | R2: 1 | S2: no_msg | T2: 0 | U2: 1 | V2: Bathinda | W2: Talwandi Sabo | X2: 0
A3: cvhtal1111 | B3: Talwandi123 | C3: CVH Talwandi Sabo | D3: Veterinary officer CVH Talwandi Sabo | E3: Hardeep Singh | F3: Veterinary Inspector | G3: 9463268157 | H3: hschgiana@gmail.com | I3: 31513 | J3: PAW Sangat Khurad | K3: CVD Teona Pujarian | L3: CVD Jaga Ram Tirath | M3: CVD Nangla | N3: CVD Gatwali | O3: PAW Lehri | Q3: ESMF0mATL3hW01T64M8G | R3: 0 | S3: no_msg | T3: 2 | U3: 1 | V3: Bathinda | W3: Talwandi Sabo | X3: 1 | Y3: CVD Teona Pujarian,CVH Talwandi Sabo,CVD Jaga Ram Tirath,CVD Nangla,CVH Natheha,CVD Kalalwala,CVD Rayia,CVH Bhagiwander,CVD Chathewala,CVH Singo,CVH Shekhpura,CVD Gatwali
A4: cvdgat7183 | B4: gsm64843 | C4: CVD Gatwali | D4: Veterinary officer CVH Talwandi Sabo | E4: Gurmeet Singh | F4: Veterinary Inspector | G4: 9878237333 | H4: gsmalkana@gmail.com | I4: 29142 | Q4: hAY69xS9kGij6EVVC0PQ | R4: 0 | S4: no_msg | T4: 2 | U4: 3 | V4: Bathinda | W4: Talwandi Sabo | X4: 0
A5: cvdteo6484 | B5: password | C5: CVD Teona Pujarian | D5: Veterinary officer CVH Talwandi Sabo | E5: Gurdeep Singh | F5: Veterinary Inspector | G5: 9463257663 | H5: gschouhan04@gmail.com | I5: 20/04/1979 | J5: PAW Sangat Khurad | Q5: JhaDaeOOIBsKqL6NExPb | R5: 0 | S5: no_msg | T5: 2 | U5: 3 | V5: Bathinda | W5: Talwandi Sabo | X5: 0
A6: pawsan2022 | B6: Pass2022 | C6: PAW Sangat Khurad | D6: Veterinary Inspector CVD Teona Pujarian | E6: Sukhpal Singh | F6: Private AI Worker | G6: 9417764968 | H6: sukh0002@gmail.com | R6: 0 | S6: no_msg | T6: 2 | U6: 4 | V6: Bathinda | W6: Talwandi Sabo | X6: 0
A7: cvdjag2309 | B7: sehaj@06 | C7: CVD Jaga Ram Tirath | D7: Veterinary Officer CVH Talwandi Sabo | E7: Sehajpreet Singh | F7: Veterinary Inspector | G7: 9320780006 | H7: sahej041@gmail.com | I7: 35955 | Q7: prRNvTsB8X7p8EgFzoUw | R7: 0 | S7: no_msg | T7: 2 | U7: 3 | V7: Bathinda | W7: Talwandi Sabo | X7: 0
A8: cvdnan4749 | B8: Khush@1234 | C8: CVD Nangla | D8: Veterinary Officer CVH Talwandi Sabo | E8: Khushdeep Singh | F8: Veterinary Inspector | G8: 7814942632 | H8: khush20072001@gmail.com | I8: 30060 | J8: PAW Lehri | Q8: 0LcSjYgZizItonymgoXT | R8: 0 | S8: no_msg | T8: 2 | U8: 3 | V8: Bathinda | W8: Talwandi Sabo | X8: 0
A9: pawleh3484 | B9: jagjeet | C9: PAW Lehri | D9: Veterinary Inspector CVD Nangla | E9: Jagjeet Singh | F9: Private AI Worker | G9: 9915772067 | H9: sjeet3377@gmail.com | R9: 0 | S9: no_msg | T9: 2 | U9: 4 | V9: Bathinda | W9: Talwandi Sabo | X9: 0
A10: cvhnat3075 | B10: Rana@12 | C10: CVH Natheha | D10: Senior Veterinary Officer Talwandi Sabo | E10: Dr. Shekher Rana | F10: Veterinary Officer | G10: 9468040548 | H10: Shekharranaaa26@gmail.com | I10: 31069 | J10: PAW Mirzeana | K10: CVD Rayia | L10: CVD Kalalwala | M10: PAW Gehlewala | Q10: 0vjS8TWdUfBeMJq1PKZG | R10: 0 | S10: no_msg | T10: 2 | U10: 2 | V10: Bathinda | W10: Talwandi Sabo | X10: 0
A11: pawmir6748 | B11: kulwant singh | C11: PAW Mirzeana | D11: Vetenary Officer CVH Natheha | E11: Kulwant Singh | F11: Private AI Worker | G11: 9781562063 | H11: ks0033453@gmail.com | R11: 0 | S11: no_msg | T11: 2 | U11: 4 | V11: Bathinda | W11: Talwandi Sabo | X11: 0
A12: cvdray1998 | B12: Gursanjh@2023 | C12: CVD Rayia | D12: Veterinary Officer CVH Natheha | E12: Sandeep Singh | F12: Veterinary Inspector | G12: 9781508812 | H12: sanndeep97815@gmail.com | I12: 35936 | J12: PAW Gehlewala | Q12: jSTIqeCCSVtJjzNq8t2r | R12: 0 | S12: no_msg | T12: 2 | U12: 3 | V12: Bathinda | W12: Talwandi Sabo | X12: 0
A13: cvdkal9978 | B13: rsjogewala | C13: CVD Kalalwala | D13: Veterinary Officer CVH Natheha | E13: Rajwinder Singh | F13: Veterinary Inspector | G13: 9464349752 | H13: singhrajwinder665@gmail.com | I13: 37092 | Q13: huZCzeQknB00uo4AZzMZ | R13: 0 | S13: no_msg | T13: 2 | U13: 3 | V13: Bathinda | W13: Talwandi Sabo | X13: 0
A14: pawgeh3110 | B14: password | C14: PAW Gehlewala | D14: Veterinary Inspector CVD Rayia | E14: Baljeet Singh | F14: Private Ai Worker | G14: 9464819260 | H14: baljitsingh7385@gmail.com | Q14: WZHwieFYxc48DVx7uZSs | R14: 0 | S14: no_msg | T14: 2 | U14: 4 | V14: Bathinda | W14: Talwandi Sabo | X14: 0
A15: cvhbha2028 | B15: bticvhbhagiwandar | C15: CVH Bhagiwander | D15: Senior Veterinary Officer Talwandi Sabo | E15: Tej ram | F15: Veterinary pharamacist | G15: 9417739565 | H15: tej2947@gmail.com | J15: CVD Chathewala | K15: PAW Natt | Q15: osM4RMvx7I9l0uXuagkj | R15: 0 | S15: no_msg | T15: 2 | U15: 2 | V15: Bathinda | W15: Talwandi Sabo | X15: 0
A16: cvdcha6789 | B16: Sekhu@123 | C16: CVD Chathewala | D16: Veterinary Officer CVH Bhagiwander | E16: satnam Singh | F16: Veterinary Inspector | G16: 78374 00143 | H16: sekhusajan@gmail.com | I16: 35955 | J16: PAW Natt | Q16: z4Ut9ag6sQ6idNZ6xnij | R16: 0 | S16: no_msg | T16: 2 | U16: 3 | V16: Bathinda | W16: Talwandi Sabo | X16: 0
A17: pawnat3879 | B17: 1987 | C17: PAW Natt | D17: Veterinary Inspector CVD Chathewala | E17: Kulwinder Singh | F17: Private AI Worker | G17: 9779361662 | H17: singhkulwinder70200@gmail.com | R17: 0 | S17: no_msg | T17: 2 | U17: 4 | V17: Bathinda | W17: Talwandi Sabo | X17: 0
A18: cvhram9293 | B18: 1998 | C18: CVH Raman Mandi | D18: Senior Veterinary Officer Talwandi Sabo | E18: Dr. Harshit | F18: Veterinary officer | G18: 7015525385 | H18: kycrattakhera96@gmail.com | I18: 27823 | J18: PAW Kamalu | K18: PAW Jajjal | L18: CVD Sekhu | Q18: 5P7dFgEHvBh9JrsJQJ4L | R18: 0 | S18: no_msg | T18: 2 | U18: 1 | V18: Bathinda | W18: Talwandi Sabo | X18: 1 | Y18: CVH Raman Mandi,CVD Sekhu,PAW Jajjal,PAW Kamalu,CVH Malkana,CVH Behman Jassa Singh,CVH Bangi Kalan,CVH Kanakwal
A19: pawkam6144 | B19: 1234 | C19: PAW Kamalu | D19: Veterinary Officer CVH Raman Mandi | E19: Bikkerjit Singh | F19: Private AI Worker | G19: 9478454831 | H19: bikkerjitsingh6@gmail.com | Q19: 6BagbTGLfgWH4oguvx9f | R19: 0 | S19: no_msg | T19: 2 | U19: 4 | V19: Bathinda | W19: Talwandi Sabo | X19: 0
A20: pawjaj4030 | B20: pass4030 | C20: PAW Jajjal | D20: Veterinary Officer CVH Raman Mandi | E20: Gurdeep Singh | F20: Private AI Worker | G20: 9530685410 | H20: gsingh83710@gmail.com | Q20: k8vDlRV0LVZVX9JnFjLM | R20: 0 | S20: no_msg | T20: 2 | U20: 4 | V20: Bathinda | W20: Talwandi Sabo | X20: 0
A21: cvdsek5978 | B21: 2000 | C21: CVD Sekhu | D21: Veterinary Officer CVH Raman Mandi | E21: Gurnam singh | F21: veterinary Inspector | G21: 9463491350 | H21: gurnamschattha@gmail.com | I21: 23538 | Q21: 4ZSZGT8R39cVPoImoD3U | R21: 0 | S21: no_msg | T21: 2 | U21: 3 | V21: Bathinda | W21: Talwandi Sabo | X21: 0
A22: cvhbeh5265 | B22: 1986 | C22: CVH Behman Jassa Singh | D22: Senior Veterinary Officer Talwandi Sabo | E22: Gagandeep Singh | F22: Rural Veterinary Pharmacist | G22: 9915156262 | H22: gagansinghsidhu86@gmail.com | J22: PAW Behman Kaur Singh | Q22: dY5SaqDi0pNSpvsfikxl | R22: 0 | S22: no_msg | T22: 2 | U22: 2 | V22: Bathinda | W22: Talwandi Sabo | X22: 0
A23: pawbeh6117 | B23: password | C23: PAW Behman Kaur Singh | D23: Veterinary officer CVH Behman Jassa Singh | E23: Balwinder Singh | F23: Private AI Worker | G23: 9464132031 | H23: binderdocter4@gmail.com | Q23: Ku7l9xeHOr5lm3A9328p | R23: 0 | S23: no_msg | T23: 2 | U23: 4 | V23: Bathinda | W23: Talwandi Sabo | X23: 0
A24: cvhban9641 | B24: Bangi@123 | C24: CVH Bangi Deepa | D24: Senior Veterinary Officer Talwandi Sabo | E24: Dr. Manpreet Singh | F24: Veterinary Officer | G24: 9551422222 | H24: gagankhemuana@gmail.com | I24: 35984 | Q24: vJPK8S8wtSyvrsP5UiCr | R24: 0 | S24: no_msg | T24: 2 | U24: 2 | V24: Bathinda | W24: Talwandi Sabo | X24: 0
A25: cvhpak2554 | B25: Pakka@123 | C25: CVH Pakka Kalan | D25: Senior Veterinary Officer Talwandi Sabo | E25: Dr.Mohit kumar | F25: veterinary Officer | G25: 7009542010 | H25: cvhpakkakalan@gmail.com | I25: 36862 | J25: PAW Gurthari | K25: CVD Phallar | L25: CVD Malwala | M25: PAW Chak Heera Singh Wala | Q25: kU3hqKU8x9oZKtwCDf9B | R25: 0 | S25: no_msg | T25: 2 | U25: 2 | V25: Bathinda | W25: Talwandi Sabo | X25: 1 | Y25: CVH Pakka Kalan,CVD Malwala,CVD Phallar,CVH Bangi Deepa,CVH Bhagwangarh
A26: pawcha3400 | B26: Gobind@1993 | C26: PAW Chak Heera Singh Wala | D26: Veterinary Officer CVH Pakka kalan | E26: Gobind Singh | F26: Private Ai Worker | G26: gobindsingh005002s@gmail.com | H26: gobindsingh005002s@gmail.com | Q26: 1p7PtGsvQRh2BPTfZQFS | R26: 0 | S26: no_msg | T26: 2 | U26: 4 | V26: Bathinda | W26: Talwandi Sabo | X26: 0
A27: pawgur7263 | B27: 5275 | C27: PAW Gurthari | D27: Veterinary Officer CVH Pakka kalan | E27: Gurmel Singh | F27: Private Ai Worker | G27: 9876852575 | H27: khushpal572@gmail.com | Q27: M7Uk1bkAJgh8mkiDkTje | R27: 0 | S27: no_msg | T27: 2 | U27: 4 | V27: Bathinda | W27: Talwandi Sabo | X27: 0
A28: cvdpha3711 | B28: 2000 | C28: CVD Phallar | D28: Veterinary Officer CVH Pakka kalan | E28: Sukhpreet Singh | F28: Veterinary Inspector | G28: 9465759552 | H28: sukhsidhu59552@gmail.com | I28: 29406 | J28: PAW Chak Heera Singh Wala | Q28: z7QR6trXHWalanuCUnXv | R28: 0 | S28: no_msg | T28: 2 | U28: 3 | V28: Bathinda | W28: Talwandi Sabo | X28: 0
A29: cvdmal8248 | B29: arsh1999 | C29: CVD Malwala | D29: Veterinary Officer CVH Pakka kalan | E29: Arshdeep Singh | F29: Veterinary Inspector | G29: 8360176910 | H29: arshdeepsingh38985@gmail.com | I29: 36764 | Q29: t4j61gaVzCzg415OiipE | R29: 0 | S29: no_msg | T29: 2 | U29: 3 | V29: Bathinda | W29: Talwandi Sabo | X29: 0
A30: cvhshe6427 | B30: 2000 | C30: CVH Shekhpura | D30: Senior Veterinary Officer Talwandi Sabo | E30: Dr Sagar | F30: Veterinary Officer | G30: 7009770572 | H30: 2000sagararora@gmail.com | J30: PAW Lelewala | Q30: YYTpjETN8P3VaWQwSUyC | R30: 0 | S30: no_msg | T30: 2 | U30: 2 | V30: Bathinda | W30: Talwandi Sabo | X30: 0
A31: pawlel4723 | B31: 1991 | C31: PAW Lelewala | D31: Veterinary Officer CVH Shekhpura | E31: BALJIT SINGH | F31: Private Ai Worker | G31: 9855741258 | H31: dhillonbaljitsingh161@gmail.com | R31: 0 | S31: no_msg | T31: 2 | U31: 4 | V31: Bathinda | W31: Talwandi Sabo | X31: 0
A32: cvhsin5995 | B32: 1683 | C32: CVH Singo | D32: Senior Veterinary Officer Talwandi Sabo | E32: Gurpal Gill | F32: Rural Veterinary Pharmacist | G32: 9876952273 | H32: gurpalgill205@gmail.com | Q32: sLmI3mmzMTIGv0PYcmFE | R32: 0 | S32: no_msg | T32: 2 | U32: 2 | V32: Bathinda | W32: Talwandi Sabo | X32: 0
A33: cvhban5886 | B33: bangidipa0000 | C33: CVH Bangi Kalan | D33: Senior Veterinary Officer Talwandi Sabo | E33: Dr Himanshu Gupta | F33: Veterinary officer | G33: 8847219859 | H33: harrygupta13@gmail.com | I33: 31048 | Q33: 10KcPcilJn73CmuprBpO | R33: 0 | S33: no_msg | T33: 2 | U33: 2 | V33: Bathinda | W33: Talwandi Sabo | X33: 0
A34: cvhlal9318 | B34: cvhbhagwangarh | C34: CVH Laleana | D34: Senior Veterinary Officer Talwandi Sabo | E34: Dr PEEYUSH | F34: Veterinary officer | G34: 9996876355 | H34: piyush00012@gmail.com | J34: PAW Mahi Nangal | Q34: g351YAEdfgUubM0JrqG7 | R34: 0 | S34: no_msg | T34: 2 | U34: 2 | V34: Bathinda | W34: Talwandi Sabo | X34: 0
A35: pawmah5541 | B35: 7777 | C35: PAW Mahi Nangal | D35: Veterinary officer CVH Talwandi Sabo | E35: Gurjant Singh | F35: Private AI Worker | G35: 8847279521 | H35: labhpreetpuniamahinangal@gmail.com | Q35: l1iy6ihgLUj7gruOtDCI | R35: 0 | S35: no_msg | T35: 2 | U35: 4 | V35: Bathinda | W35: Talwandi Sabo | X35: 0
A36: cvhbha4483 | B36: Ranjit84 | C36: CVH Bhagwangarh | D36: Senior Veterinary Officer Talwandi Sabo | E36: Ranjit Singh | F36: veterinary pharmacist | G36: 9463417628 | H36: ranjitsingh17441@gmail.com | J36: PAW Shergarh | Q36: LYUPybGpxkzPEQGUYETH | R36: 0 | S36: no_msg | T36: 2 | U36: 2 | V36: Bathinda | W36: Talwandi Sabo | X36: 0
A37: pawshe5168 | B37: password | C37: PAW Shergarh | D37: Veterinary Officer CVH Bhagwangarh | E37: Gurmohandeep Singh | F37: Private Ai Worker | G37: 8427340900 | H37: rinkubutter5757@gmail.com | R37: 1 | S37: no_msg | T37: 2 | U37: 4 | V37: Bathinda | W37: Talwandi Sabo | X37: 0
A38: cvhkan3005 | B38: harshit12 | C38: CVH Kanakwal | D38: Senior Veterinary Officer Talwandi Sabo | E38: Dr Pooja | F38: Veterinary Officer | G38: 7015525385 | H38: kycrattakhera96@gmail.com | N38: 0 | Q38: krB3iqNfkfOKvhVKUhsv | R38: 0 | S38: no_msg | T38: 2 | U38: 2 | V38: Bathinda | W38: Talwandi Sabo | X38: 0
A39: cvhmal305 | B39: password | C39: CVH Malkana | D39: Senior Veterinary Officer Talwandi Sabo | E39: Swarn Singh | F39: Rural Veterinary Pharmacist | G39: 9814618216 | H39: siviaswarn7@gmail.com | Q39: 0ibDulsoaC87UYlgCjOV | R39: 0 | S39: no_msg | T39: 2 | U39: 2 | V39: Bathinda | W39: Talwandi Sabo | X39: 0
A40: pawkai817 | B40: password | C40: PAW Kaile Wander | D40: Veterinary Officer CVH Bhagwangarh | E40: Randeep Singh | F40: Private AI Worker | G40: Add Mobile | Q40: 1 | R40: 1 | S40: no_msg | T40: 2 | U40: 4 | V40: Bathinda | W40: Talwandi Sabo | X40: 0
...

Sheet Form responses
A1: Timestamp | B1: Start Date of reporting Month | C1: End Date of reporting Month | D1: Institute Name | E1: User ID | F1: User Role | G1: Tehsil | H1: District | I1: New Case Equine | J1: New Case Bovine | K1: New Case Other | L1: New Case Dogs | M1: Old Case Equine | N1: Old Case Bovine | O1: Old Case Other | P1: Old Case Dogs | Q1: No. Of Camp Organised | R1: Farmers Arrived in Capm | S1: Case Treated In Camp | T1: Gaushala Cases | U1: Bovine Castrations | V1: Other Castrations | W1: No. of Pregnancy Diagnosis (Paid) | X1: A.H. Certificate Small Animals | Y1: A.H. Certificate Large Animals | Z1: Post Mortem Small Animals | AA1: Post Mortem Large Animals | AB1: Post Mortem Vetro Legal | AC1: PM poultry | AD1: PM Dogs Vetro legal | AE1: H.S. Vaccine Doses Received | AF1: H.S. Vaccine Doses Used | AG1: H.S. Vaccine Animal Vaccinated | AH1: FMD. Vaccine Doses Received | AI1: FMD. Vaccine Doses Used | AJ1: FMD. Vaccine Animal Vaccinated | AK1: Black Quarter Doses Received | AL1: Black Quarter Doses Used | AM1: Black Quarter Animal Vaccinated | AN1: Brucellosis Vaccine Doses Received | AO1: Brucellosis Vaccine Doses Used | AP1: Brucellosis Vaccine Animal Vaccinated | AQ1: Entero Toximia Vaccine Doses Received | AR1: Entero Toximia Vaccine Doses Used | AS1: Entero Toximia Vaccine Animals Vaccinated | AT1: Swine Fever Vaccine Doses Received | AU1: Swine Fever Vaccine Doses Used | AV1: Swine Fever Vaccine Animal Vaccinated | AW1: Goat Pox Vaccine Doses Received | AX1: Goat Pox Vaccine Doses Used | AY1: Goat Pox Vaccine Animal Vaccinated | AZ1: PPR Doses Received | BA1: PPR Doses Used | BB1: PPR Animal Cover | BC1: Rabies Doses Received | BD1: Rabies Doses Used | BE1: Rabies animal vaccinated | BF1: AI HF Straws | BG1: Cover HF Straws | BH1: AI Jersey Straws | BI1: Cover Jersey Straws | BJ1: AI Cross Breed Straws | BK1: Cover Cross Breed Straws | BL1: AI Sahiwal Straws | BM1: Cover Sahiwal Straws | BN1: AI HF ETT Straws | BO1: Cover HF ETT Straws | BP1: AI Jersey ETT Straws | BQ1: Cover Jersey ETT Straws | BR1: AI Sexed HF Straws | BS1: Cover Sexed HF Straws | BT1: AI Jersey Sexed Straws | BU1: Cow Cover Jersey Sexed | BV1: AI Cross Breed Sexed Straws | BW1: Cover Cross Breed Sexed | BX1: AI Sahiwal Sexed Straws | BY1: Cow Cover Sahiwal Sexed | BZ1: AI Done With Murrah Straws | CA1: Cover Murrah Straws | CB1: AI Nili-Ravi Straws | CC1: Cover Nili-Ravi Straws | CD1: AI Sexed MU Straws | CE1: Cover Sexed MU Straws | CF1: AI Nili-Ravi Sexed Straws | CG1: Buffalo Cover Nili-Ravi Sexed | CH1: HF Tested | CI1: HF Found Postive | CJ1: Jersey Tested | CK1: Jersey Found Postive | CL1: Cross Breed Tested | CM1: Cross Breed Found Postive | CN1: Sahiwal Cow Tested | CO1: Sahiwal Found Postive | CP1: HF ETT Tested | CQ1: HF ETT Found Postive | CR1: Jessey ETT Tested | CS1: Jessey ETT Found Postive | CT1: Sexed HF Tested | CU1: Sexed HF Found Postive | CV1: Jersey Sexed Tested | CW1: Jersey Sexed Found Positive | CX1: CB Sexed Tested | CY1: CB Sexed Found Positive | CZ1: sahiwal Sexed Tested | DA1: sahiwal Sexed found positive | DB1: Murrah Tested | DC1: Murrah Found Postive | DD1: Nili Ravi Tested | DE1: Nili Found Postive | DF1: Sexed MU Tested | DG1: Sexed MU Found Postive | DH1: Nilli-ravi Sexed tested | DI1: Nilli-ravi Sexed found Positive | DJ1: Other 2 Tested | DK1: Other 2 Found Positive | DL1: HF Male Calves | DM1: HF female Calves | DN1: Jersey Male Calves | DO1: Jersey female Calves | DP1: Cross Breed Male Calves | DQ1: Cross Breed female Calves | DR1: Sahiwal Male Calves | DS1: Sahiwal female Calves | DT1: HF ETT Male Calves | DU1: HF ETT female Calves | DV1: Jersey ETT Male Calves | DW1: Jersey ETT female Calves | DX1: Sexed HF Male Calves | DY1: Sexed HF female Calves | DZ1: Jersey Sexed Male Calves | EA1: Jersey Sexed female Calves | EB1: CB Sexed Male Calves | EC1: CB Sexed female Calves | ED1: Sahiwal Sexed Male Calves | EE1: Sahiwal Sexed female Calves | EF1: Murrah Male Calves | EG1: Murrah Female Calves | EH1: Nili Ravi Male Calves | EI1: Nili Ravi Female Calves | EJ1: Sexed MU Male Calves | EK1: Sexed MU female Calves | EL1: Nilli-Ravi Sexed Male Calves | EM1: Nilli-Ravi Sexed female Calves | EN1: Other 1 Male Calves | EO1: Other 1 Female Calves | EP1: Other 2 Male Calves | EQ1: Other 2 Female Calves | ER1: HF Straws Received This Month | ES1: Jesey Straws Received This Month | ET1: Cross Breed Straws Received This Month | EU1: Sahiwal Straws Received This Month | EV1: HF ETT Straws Received This Month | EW1: Jersey ETT Straws Received This Month | EX1: Sexed HF Straws Received This Month | EY1: Jersey Sexed Straws Received This Month | EZ1: CB Sexed Straws Received This Month | FA1: Sahiwal Sexed Straws Received This Month | FB1: Murrah Recieved This Month | FC1: Nili Ravi Straws Received This Month | FD1: MU Sexed Straws Received This Month | FE1: Nilli-Ravi Sexed Straws Received This Month | FF1: Other 1 Received This Month | FG1: Other 2 Straws Received This Month | FH1: HF Straws Issued to AIW This Month | FI1: Jersey Straws Issued To AIW This Month | FJ1: Cross Breed Straws Issued to AIW during Month | FK1: Sahiwal Straws Issued to AIW during Month | FL1: HF ETT Straws Issued to AIW during Month | FM1: Jersey ETT Straws Issued to AIW during Month | FN1: Sexed HF Straws Issued to AIW during Month | FO1: Jersey Sexed Straws Issued to AIW This Month | FP1: CB Sexed Straws Issued to AIW This Month | FQ1: Sahiwal Sexed Straws Issued to AIW This Month | FR1: Murrah Straws Issued to AIW during Month | FS1: Nili Ravi Straws Issued to AIW during Month | FT1: Sexed MU Straws Issued to AIW during Month | FU1: Nilli-Ravi Sexed Straws Issued to AIW This Month | FV1: other 1 Issued to AIW during Month | FW1: Other 2 Straws Issued to AIW during Month | FX1: No. of School Lect | FY1: Jesey Straws Used INAPH during month | FZ1: No of Students | GA1: Sahiwal Straws Used INAPH during month | GB1: HF ETT Straws Used INAPH during month | GC1: Jersey ETT Straws Used INAPH This month | GD1: HF Sexed Straws Used INAPH during month | GE1: Jersey Sexed Straws Used INAPH during month | GF1: CB Sexed Straws Used INAPH during month | GG1: Sahiwal Sexed Straws Used INAPH during month | GH1: Murrah Straws Used INAPH This month | GI1: Nili Ravi Straws Used INAPH This month | GJ1: MU Sexed Straws Used INAPH during month | GK1: Nili Ravi Sexed INAPH during | GL1: Other 1 INAPH | GM1: Other 2 INAPH | GN1: Fecal Test | GO1: Blood Test | GP1: Urine Test | GQ1: Milk Test | GR1: reciept number
A2: 44570.865 | C2: 44555 | F2: 3 | G2: Talwandi Sabo | H2: Bathinda | I2: 0 | J2: 0 | K2: 0 | L2: 0 | M2: 0 | N2: 0 | O2: 0 | P2: 0 | Q2: 0 | R2: 0 | S2: 0 | T2: 0 | U2: 0 | V2: 0 | W2: 0 | X2: 0 | Y2: 0 | Z2: 0 | AA2: 0 | AB2: 0 | AC2: 0 | AD2: 0 | AE2: 0 | AF2: 0 | AG2: 0 | AH2: 0 | AI2: 0 | AJ2: 0 | AK2: 0 | AL2: 0 | AM2: 0 | AN2: 0 | AO2: 0 | AP2: 0 | AQ2: 0 | AR2: 0 | AS2: 0 | AT2: 0 | AU2: 0 | AV2: 0 | AW2: 0 | AX2: 0 | AY2: 0 | BA2: 0 | BB2: 0 | BC2: 0 | BD2: 0 | BF2: 0 | BG2: 0 | BH2: 0 | BI2: 0 | BJ2: 0 | BK2: 0 | BL2: 0 | BM2: 0 | BN2: 0 | BO2: 0 | BP2: 0 | BQ2: 0 | BR2: 0 | BS2: 0 | BZ2: 0 | CA2: 0 | CB2: 0 | CC2: 0 | CD2: 0 | CE2: 0 | CH2: 0 | CI2: 0 | CJ2: 0 | CK2: 0 | CL2: 0 | CM2: 0 | CN2: 0 | CO2: 0 | CP2: 0 | CQ2: 0 | CR2: 0 | CS2: 0 | CT2: 0 | CU2: 0 | DB2: 0 | DC2: 0 | DD2: 0 | DE2: 0 | DF2: 0 | DG2: 0 | DL2: 0 | DM2: 0 | DN2: 0 | DO2: 0 | DP2: 0 | DQ2: 0 | DR2: 0 | DS2: 0 | DT2: 0 | DU2: 0 | DV2: 0 | DW2: 0 | DX2: 0 | DY2: 0 | EF2: 0 | EG2: 0 | EH2: 0 | EI2: 0 | EJ2: 0 | EK2: 0 | EN2: 0 | EO2: 0 | ER2: 0 | ES2: 0 | ET2: 0 | EU2: 0 | EV2: 0 | EW2: 0 | EX2: 0 | FB2: 0 | FC2: 0 | FD2: 0 | FF2: 0 | FH2: 0 | FI2: 0 | FJ2: 0 | FK2: 0 | FL2: 0 | FM2: 0 | FN2: 0 | FR2: 0 | FS2: 0 | FT2: 0 | FV2: 0 | FX2: 0 | FY2: 0 | FZ2: 0 | GA2: 0 | GB2: 0 | GC2: 0 | GH2: 0 | GI2: 0 | GL2: 0 | GR2: {=if(B2:B394<>"",row(A2:A394)-1,"")}
A3: 45777.401 | B3: 45717 | C3: 45747 | D3: CVH Talwandi Sabo | F3: 2 | G3: Talwandi Sabo | H3: Bathinda | AE3: 0 | AH3: 0 | AK3: 0 | AN3: 200 | AQ3: 0 | AT3: 0 | AW3: 0 | ER3: 134 | ES3: 0 | ET3: 42 | EU3: 124 | EV3: 24 | EW3: 0 | EX3: 0 | EY3: 0 | EZ3: 0 | FA3: 0 | FB3: 240 | FC3: 20 | GR3: 2
A4: 45777.402 | B4: 45746 | C4: 45747 | D4: CVD Teona Pujarian | F4: 3 | G4: Talwandi Sabo | H4: Bathinda | AE4: 0 | AH4: 0 | AK4: 0 | AN4: 0 | AQ4: 0 | AT4: 0 | AW4: 0 | ER4: 32 | ES4: 0 | ET4: 12 | EU4: 31 | EV4: 6 | EW4: 0 | EX4: 0 | EY4: 0 | EZ4: 0 | FA4: 0 | FB4: 60 | FC4: 6 | GR4: 3
A5: 45777.402 | B5: 45746 | C5: 45747 | D5: CVD Jaga Ram Tirath | F5: 3 | G5: Talwandi Sabo | H5: Bathinda | AE5: 0 | AH5: 0 | AK5: 0 | AN5: 330 | AQ5: 0 | AT5: 0 | AW5: 0 | ER5: 32 | ES5: 0 | ET5: 12 | EU5: 31 | EV5: 6 | EW5: 0 | EX5: 0 | EY5: 0 | EZ5: 0 | FA5: 0 | FB5: 60 | FC5: 6 | GR5: 4
A6: 45777.402 | B6: 45746 | C6: 45747 | D6: CVD Nangla | F6: 3 | G6: Talwandi Sabo | H6: Bathinda | AE6: 0 | AH6: 0 | AK6: 0 | AN6: 0 | AQ6: 0 | AT6: 0 | AW6: 0 | ER6: 32 | ES6: 0 | ET6: 12 | EU6: 31 | EV6: 6 | EW6: 0 | EX6: 0 | EY6: 0 | EZ6: 0 | FA6: 0 | FB6: 60 | FC6: 6 | GR6: 5
A7: 45777.402 | B7: 45746 | C7: 45747 | D7: CVH Natheha | F7: 3 | G7: Talwandi Sabo | H7: Bathinda | AE7: 0 | AH7: 0 | AK7: 0 | AN7: 350 | AQ7: 0 | AT7: 0 | AW7: 0 | ER7: 0 | ES7: 0 | ET7: 0 | EU7: 0 | EV7: 0 | EW7: 0 | EX7: 0 | EY7: 0 | EZ7: 0 | FA7: 0 | FB7: 0 | FC7: 0 | GR7: 6
A8: 45777.402 | B8: 45746 | C8: 45747 | D8: CVD Rayia | F8: 3 | G8: Talwandi Sabo | H8: Bathinda | AE8: 0 | AH8: 0 | AK8: 0 | AN8: 200 | AQ8: 0 | AT8: 0 | AW8: 0 | ER8: 32 | ES8: 0 | ET8: 12 | EU8: 31 | EV8: 6 | EW8: 0 | EX8: 0 | EY8: 0 | EZ8: 0 | FA8: 0 | FB8: 60 | FC8: 6 | GR8: 7
A9: 45777.402 | B9: 45746 | C9: 45747 | D9: CVD Kalalwala | F9: 3 | G9: Talwandi Sabo | H9: Bathinda | AE9: 0 | AH9: 0 | AK9: 0 | AN9: 140 | AQ9: 0 | AT9: 0 | AW9: 0 | ER9: 32 | ES9: 0 | ET9: 11 | EU9: 32 | EV9: 6 | EW9: 0 | EX9: 0 | EY9: 0 | EZ9: 0 | FA9: 0 | FB9: 60 | FC9: 6 | GR9: 8
A10: 45777.402 | B10: 45746 | C10: 45747 | D10: CVD Chathewala | F10: 3 | G10: Talwandi Sabo | H10: Bathinda | AE10: 0 | AH10: 0 | AK10: 0 | AN10: 90 | AQ10: 0 | AT10: 0 | AW10: 0 | ER10: 32 | ES10: 0 | ET10: 10 | EU10: 33 | EV10: 6 | EW10: 0 | EX10: 0 | EY10: 0 | EZ10: 0 | FA10: 0 | FB10: 60 | FC10: 6 | GR10: 9
A11: 45777.403 | B11: 45746 | C11: 45747 | D11: CVH Raman Mandi | F11: 3 | G11: Talwandi Sabo | H11: Bathinda | AE11: 0 | AH11: 0 | AK11: 0 | AN11: 250 | AQ11: 0 | AT11: 0 | AW11: 0 | ER11: 96 | ES11: 0 | ET11: 30 | EU11: 99 | EV11: 18 | EW11: 0 | EX11: 0 | EY11: 0 | EZ11: 0 | FA11: 4 | FB11: 180 | FC11: 15 | FD11: 10 | GR11: 10
A12: 45777.403 | B12: 45717 | C12: 45747 | D12: CVD Gatwali | F12: 3 | G12: Talwandi Sabo | H12: Bathinda | AE12: 0 | AH12: 0 | AK12: 0 | AN12: 0 | AQ12: 0 | AT12: 0 | AW12: 0 | ER12: 32 | ES12: 0 | ET12: 10 | EU12: 26 | EV12: 8 | EW12: 0 | EX12: 0 | EY12: 0 | EZ12: 0 | FA12: 0 | FB12: 60 | FC12: 21 | GR12: 11
A13: 45777.403 | B13: 45746 | C13: 45747 | D13: CVD Sekhu | F13: 3 | G13: Talwandi Sabo | H13: Bathinda | AE13: 0 | AH13: 0 | AK13: 0 | AN13: 250 | AQ13: 0 | AT13: 0 | AW13: 0 | ER13: 32 | ES13: 0 | ET13: 10 | EU13: 31 | EV13: 8 | EW13: 0 | EX13: 0 | EY13: 0 | EZ13: 0 | FA13: 0 | FB13: 60 | FC13: 6 | GR13: 12
A14: 45777.403 | B14: 45746 | C14: 45747 | D14: CVH Behman Jassa Singh | F14: 2 | G14: Talwandi Sabo | H14: Bathinda | AE14: 0 | AH14: 0 | AK14: 0 | AN14: 300 | AQ14: 0 | AT14: 0 | AW14: 0 | ES14: 0 | ET14: 0 | EU14: 0 | EW14: 0 | EX14: 0 | EY14: 0 | EZ14: 0 | FA14: 0 | GR14: 13
A15: 45777.403 | B15: 45746 | C15: 45747 | D15: CVH Bangi Deepa | F15: 2 | G15: Talwandi Sabo | H15: Bathinda | AE15: 0 | AH15: 0 | AK15: 0 | AN15: 0 | AQ15: 0 | AT15: 0 | AW15: 0 | ER15: 32 | ES15: 0 | ET15: 10 | EU15: 31 | EV15: 8 | EW15: 0 | EX15: 0 | EY15: 0 | EZ15: 0 | FA15: 0 | FB15: 60 | FC15: 6 | GR15: 14
A16: 45777.403 | B16: 45746 | C16: 45747 | D16: CVH Pakka Kalan | F16: 2 | G16: Talwandi Sabo | H16: Bathinda | AE16: 0 | AH16: 0 | AK16: 0 | AN16: 500 | AQ16: 0 | AT16: 0 | AW16: 0 | ER16: 96 | ES16: 0 | ET16: 30 | EU16: 93 | EV16: 20 | EW16: 0 | EX16: 4 | EY16: 0 | EZ16: 0 | FA16: 0 | FB16: 185 | FC16: 15 | GR16: 15
A17: 45777.403 | B17: 45746 | C17: 45747 | D17: CVD Phallar | F17: 3 | G17: Talwandi Sabo | H17: Bathinda | AE17: 0 | AH17: 0 | AK17: 0 | AN17: 430 | AQ17: 0 | AT17: 0 | AW17: 0 | ER17: 32 | ES17: 0 | ET17: 10 | EU17: 31 | EV17: 6 | EW17: 0 | EX17: 0 | EY17: 0 | EZ17: 0 | FA17: 0 | FB17: 62 | FC17: 6 | GR17: 16
A18: 45777.403 | B18: 45746 | C18: 45747 | D18: CVD Malwala | F18: 3 | G18: Talwandi Sabo | H18: Bathinda | AE18: 0 | AH18: 0 | AK18: 0 | AN18: 220 | AQ18: 0 | AT18: 0 | AW18: 0 | ER18: 32 | ES18: 0 | ET18: 10 | EU18: 31 | EV18: 6 | EW18: 0 | EX18: 0 | EY18: 0 | EZ18: 0 | FA18: 0 | FB18: 62 | FC18: 6 | GR18: 17
A19: 45777.404 | B19: 45746 | C19: 45747 | D19: CVH Shekhpura | F19: 2 | G19: Talwandi Sabo | H19: Bathinda | AE19: 0 | AH19: 0 | AK19: 0 | AN19: 0 | AQ19: 0 | AT19: 0 | AW19: 0 | ES19: 0 | ET19: 0 | EU19: 0 | EW19: 0 | EX19: 0 | EY19: 0 | EZ19: 0 | FA19: 0 | GR19: 18
A20: 45777.404 | B20: 45746 | C20: 45747 | D20: CVH Singo | F20: 2 | G20: Talwandi Sabo | H20: Bathinda | AE20: 0 | AH20: 0 | AK20: 0 | AN20: 200 | AQ20: 0 | AT20: 0 | AW20: 0 | ES20: 0 | ET20: 0 | EU20: 0 | EW20: 0 | EX20: 0 | EY20: 0 | EZ20: 0 | FA20: 0 | GR20: 19
A21: 45777.404 | B21: 45746 | C21: 45747 | D21: CVH Bangi Kalan | F21: 2 | G21: Talwandi Sabo | H21: Bathinda | AE21: 0 | AH21: 0 | AK21: 0 | AN21: 350 | AQ21: 0 | AT21: 0 | AW21: 0 | ER21: 64 | ES21: 0 | ET21: 20 | EU21: 62 | EV21: 12 | EW21: 0 | EX21: 0 | EY21: 0 | EZ21: 0 | FA21: 0 | FB21: 122 | FC21: 12 | GR21: 20
A22: 45777.404 | B22: 45746 | C22: 45747 | D22: CVH Laleana | F22: 2 | G22: Talwandi Sabo | H22: Bathinda | AE22: 0 | AH22: 0 | AK22: 0 | AN22: 340 | AQ22: 0 | AT22: 0 | AW22: 0 | ES22: 0 | ET22: 0 | EU22: 0 | EW22: 0 | EX22: 0 | EY22: 0 | EZ22: 0 | FA22: 0 | FB22: 0 | GR22: 21
A23: 45777.404 | B23: 45746 | C23: 45747 | D23: CVH Bhagwangarh | F23: 2 | G23: Talwandi Sabo | H23: Bathinda | AE23: 0 | AH23: 0 | AK23: 0 | AN23: 430 | AQ23: 0 | AT23: 0 | AW23: 0 | ES23: 0 | ET23: 0 | EU23: 0 | EW23: 0 | EX23: 0 | EY23: 0 | EZ23: 0 | FA23: 0 | FB23: 0 | GR23: 22
A24: 45777.404 | B24: 45746 | C24: 45747 | D24: CVH Kanakwal | F24: 2 | G24: Talwandi Sabo | H24: Bathinda | AE24: 0 | AH24: 0 | AK24: 0 | AN24: 330 | AQ24: 0 | AT24: 0 | AW24: 0 | ES24: 0 | ET24: 0 | EU24: 0 | EW24: 0 | EX24: 0 | EY24: 0 | EZ24: 0 | FA24: 0 | FB24: 0 | GR24: 23
A25: 45777.403 | B25: 45746 | C25: 45747 | D25: PAW Gurthari | F25: 3 | G25: Talwandi Sabo | H25: Bathinda | AE25: 0 | AH25: 0 | AK25: 0 | AN25: 0 | AQ25: 0 | AT25: 0 | AW25: 0 | ES25: 0 | ET25: 0 | EU25: 15 | EW25: 0 | EX25: 0 | EY25: 0 | EZ25: 0 | FA25: 0 | GR25: 24
A26: 45777.402 | B26: 45746 | C26: 45747 | D26: CVH Bhagiwander | F26: 3 | G26: Talwandi Sabo | H26: Bathinda | AE26: 0 | AH26: 0 | AK26: 0 | AN26: 120 | AQ26: 0 | AT26: 0 | AW26: 0 | ES26: 0 | ET26: 0 | EU26: 0 | EV26: 35 | EW26: 0 | EX26: 0 | EY26: 0 | EZ26: 0 | FA26: 0 | FB26: 14 | FC26: 15 | GR26: 25
A27: 45777.404 | B27: 45746 | C27: 45747 | D27: CVH Malkana | F27: 2 | G27: Talwandi Sabo | H27: Bathinda | AE27: 0 | AH27: 0 | AK27: 0 | AN27: 500 | AQ27: 0 | AT27: 0 | AW27: 0 | ES27: 0 | ET27: 0 | EU27: 0 | EW27: 0 | EX27: 0 | EY27: 0 | EZ27: 0 | FA27: 0 | FB27: 0 | FD27: 10 | GR27: 26
A28: 45777.405 | B28: 45748 | C28: 45772 | D28: CVH Natheha | E28: cvhnat3075 | F28: 2 | G28: Talwandi Sabo | H28: Bathinda | J28: 54 | AH28: 3200 | AI28: 1600 | AJ28: 1600 | BZ28: 15 | CA28: 12 | CB28: 15 | CC28: 11 | FB28: 15 | FC28: 15 | GR28: 27
A29: 45777.44 | B29: 45748 | C29: 45772 | D29: CVH Bhagwangarh | E29: cvhbha4483 | F29: 2 | G29: Talwandi Sabo | H29: Bathinda | J29: 70 | N29: 30 | AH29: 4000 | AI29: 1600 | AJ29: 1600 | CP29: 26 | CQ29: 16 | DB29: 27 | DC29: 15 | DN29: 3 | DO29: 5 | EF29: 4 | EG29: 6 | GR29: 28
A30: 45777.442 | B30: 45748 | C30: 45772 | D30: PAW Jajjal | E30: pawjaj4030 | F30: 4 | G30: Talwandi Sabo | H30: Bathinda | BL30: 15 | BM30: 11 | BZ30: 15 | CA30: 12 | CB30: 15 | CC30: 11 | CP30: 20 | CQ30: 12 | DB30: 19 | DC30: 14 | DD30: 17 | DE30: 12 | EU30: 15 | FB30: 15 | FC30: 15 | GR30: 29
A31: 45777.444 | B31: 45748 | C31: 45772 | D31: CVD Sekhu | E31: cvdsek5978 | F31: 3 | G31: Talwandi Sabo | H31: Bathinda | J31: 40 | N31: 38 | T31: 20 | AH31: 2250 | AI31: 2250 | AJ31: 2250 | BZ31: 15 | CA31: 15 | CH31: 2 | CI31: 1 | CP31: 6 | CQ31: 2 | DB31: 10 | DC31: 6 | DD31: 18 | DE31: 9 | DL31: 2 | DM31: 1 | DR31: 1 | DS31: 2 | EF31: 12 | EG31: 6 | EH31: 3 | EI31: 9 | EX31: 10 | FB31: 15 | GR31: 30
A32: 45777.464 | B32: 45748 | C32: 45772 | D32: CVD Teona Pujarian | E32: cvdteo6484 | F32: 3 | G32: Talwandi Sabo | H32: Bathinda | J32: 64 | K32: 5 | L32: 1 | N32: 2 | O32: 5 | U32: 2 | AH32: 1500 | AI32: 700 | AJ32: 700 | BZ32: 15 | CA32: 15 | CN32: 45 | CO32: 32 | DB32: 30 | DC32: 20 | DR32: 10 | DS32: 12 | EF32: 5 | EG32: 3 | FB32: 15 | GR32: 31
A33: 45777.472 | B33: 45748 | C33: 45772 | D33: PAW Gurthari | E33: pawgur7263 | F33: 4 | G33: Talwandi Sabo | H33: Bathinda | BL33: 15 | BM33: 9 | BN33: 30 | BO33: 21 | EV33: 30 | GR33: 32
A34: 45777.478 | B34: 45748 | C34: 45772 | D34: CVD Gatwali | E34: cvdgat7183 | F34: 3 | G34: Talwandi Sabo | H34: Bathinda | J34: 55 | K34: 6 | N34: 12 | O34: 3 | AH34: 1750 | AI34: 800 | AJ34: 800 | BR34: 2 | BS34: 2 | CH34: 3 | CI34: 2 | CN34: 3 | CO34: 2 | CP34: 19 | CQ34: 14 | DB34: 45 | DC34: 31 | DD34: 13 | DE34: 9 | DR34: 4 | DS34: 4 | EF34: 4 | EG34: 4 | EX34: 10 | GR34: 33
A35: 45777.483 | B35: 45748 | C35: 45772 | D35: CVH Shekhpura | E35: cvhshe6427 | F35: 2 | G35: Talwandi Sabo | H35: Bathinda | J35: 28 | K35: 2 | N35: 10 | O35: 1 | AH35: 4600 | AI35: 1100 | AJ35: 1100 | CH35: 2 | DB35: 3 | DC35: 1 | DL35: 1 | EF35: 1 | EG35: 2 | GR35: 34
A36: 45777.484 | B36: 45748 | C36: 45772 | D36: CVH Malkana | E36: cvhmal305 | F36: 2 | G36: Talwandi Sabo | H36: Bathinda | J36: 50 | N36: 50 | AH36: 4600 | AI36: 1150 | AJ36: 1150 | CD36: 10 | CE36: 8 | GR36: 35
A37: 45777.487 | B37: 45748 | C37: 45772 | D37: CVH Bangi Deepa | E37: cvhban9641 | F37: 2 | G37: Talwandi Sabo | H37: Bathinda | J37: 72 | N37: 36 | AH37: 4200 | AI37: 1000 | AJ37: 1000 | BL37: 15 | BM37: 11 | BN37: 45 | BO37: 32 | BR37: 4 | BS37: 3 | CH37: 5 | CI37: 3 | CP37: 11 | CQ37: 6 | CT37: 6 | DF37: 5 | DL37: 2 | DM37: 2 | DP37: 2 | DQ37: 2 | DR37: 2 | DS37: 1 | DT37: 1 | DU37: 2 | DW37: 1 | EF37: 2 | EG37: 2 | EU37: 15 | EV37: 45 | EX37: 10 | GR37: 36
A38: 45777.497 | B38: 45748 | C38: 45772 | D38: CVD Phallar | E38: cvdpha3711 | F38: 3 | G38: Talwandi Sabo | H38: Bathinda | J38: 45 | N38: 30 | T38: 25 | AH38: 4600 | AI38: 2000 | AJ38: 2000 | BF38: 15 | BG38: 11 | BZ38: 15 | CA38: 12 | CH38: 15 | CI38: 7 | CP38: 30 | CQ38: 13 | DB38: 15 | DC38: 7 | DP38: 3 | DQ38: 4 | DR38: 4 | DS38: 4 | EF38: 7 | EG38: 7 | ER38: 15 | FB38: 15 | GR38: 37
A39: 45777.504 | B39: 45748 | C39: 45772 | D39: CVH Singo | E39: cvhsin5995 | F39: 2 | G39: Talwandi Sabo | H39: Bathinda | J39: 50 | N39: 21 | AH39: 2000 | AI39: 850 | AJ39: 850 | CP39: 5 | CQ39: 2 | DL39: 2 | DM39: 1 | EF39: 2 | EG39: 1 | GR39: 38
A40: 45777.508 | B40: 45748 | C40: 45772 | D40: CVD Malwala | E40: cvdmal8248 | F40: 3 | G40: Talwandi Sabo | H40: Bathinda | J40: 52 | N40: 35 | W40: 3 | AH40: 3100 | AI40: 1500 | AJ40: 1500 | BR40: 2 | BS40: 2 | BZ40: 15 | CA40: 15 | DB40: 30 | DC40: 15 | EF40: 30 | EG40: 23 | EX40: 5 | FB40: 15 | GR40: 39
...

Sheet Reports
G1: Monthly Report of | J1: CVH Malkana | M1: From | N1: 46113 | P1: To | Q1: 46142
K2: =V61&" "&V62 -> Tehsil - Talwandi Sabo Contact No: 9814618216
B3: OUTDOOR CASE REPORT
B4: ='Form responses'!I1 -> New Case Equine | C4: ='Form responses'!J1 -> New Case Bovine | D4: ='Form responses'!K1 -> New Case Other | E4: Total New OPD | F4: ='Form responses'!L1 -> New Case Dogs | G4: ='Form responses'!M1 -> Old Case Equine | H4: ='Form responses'!N1 -> Old Case Bovine | I4: ='Form responses'!O1 -> Old Case Other | J4: ='Form responses'!P1 -> Old Case Dogs | K4: ='Form responses'!Q1 -> No. Of Camp Organised | L4: ='Form responses'!R1 -> Farmers Arrived in Capm | M4: ='Form responses'!S1 -> Case Treated In Camp | N4: ='Form responses'!T1 -> Gaushala Cases | O4: Total New Case Treated including Gaushala /camp | P4: Total Old Case Treated | R4: ='Form responses'!U1 -> Bovine Castrations | S4: ='Form responses'!V1 -> Other Castrations | T4: ='Form responses'!W1 -> No. of Pregnancy Diagnosis (Paid) | U4: ='Form responses'!X1 -> A.H. Certificate Small Animals | V4: ='Form responses'!Y1 -> A.H. Certificate Large Animals | W4: ='Form responses'!Z1 -> Post Mortem Small Animals | X4: ='Form responses'!AA1 -> Post Mortem Large Animals | Y4: ='Form responses'!AB1 -> Post Mortem Vetro Legal | ... AA4: ='Form responses'!AD1 -> PM Dogs Vetro legal
B5: =sumifs('Form responses'!I2:I63,'Form responses'!$C$2:$C63,">="&$N$1,'Form responses'!$C$2:$C63,"<="&$Q$1,'Form responses'!$D$2:$D63,$J$1) -> 0 | C5: =sumifs('Form responses'!J2:J63,'Form responses'!$C$2:$C63,">="&$N$1,'Form responses'!$C$2:$C63,"<="&$Q$1,'Form responses'!$D$2:$D63,$J$1) -> 40 | D5: =sumifs('Form responses'!K2:K63,'Form responses'!$C$2:$C63,">="&$N$1,'Form responses'!$C$2:$C63,"<="&$Q$1,'Form responses'!$D$2:$D63,$J$1) -> 0 | E5: =SUM(B5:D5) -> 40 | F5: =sumifs('Form responses'!L2:L63,'Form responses'!$C$2:$C63,">="&$N$1,'Form responses'!$C$2:$C63,"<="&$Q$1,'Form responses'!$D$2:$D63,$J$1) -> 0 | G5: =sumifs('Form responses'!M2:M63,'Form responses'!$C$2:$C63,">="&$N$1,'Form responses'!$C$2:$C63,"<="&$Q$1,'Form responses'!$D$2:$D63,$J$1) -> 0 | H5: =sumifs('Form responses'!N2:N63,'Form responses'!$C$2:$C63,">="&$N$1,'Form responses'!$C$2:$C63,"<="&$Q$1,'Form responses'!$D$2:$D63,$J$1) -> 40 | I5: =sumifs('Form responses'!O2:O63,'Form responses'!$C$2:$C63,">="&$N$1,'Form responses'!$C$2:$C63,"<="&$Q$1,'Form responses'!$D$2:$D63,$J$1) -> 0 | J5: =sumifs('Form responses'!P2:P63,'Form responses'!$C$2:$C63,">="&$N$1,'Form responses'!$C$2:$C63,"<="&$Q$1,'Form responses'!$D$2:$D63,$J$1) -> 0 | K5: =sumifs('Form responses'!Q2:Q63,'Form responses'!$C$2:$C63,">="&$N$1,'Form responses'!$C$2:$C63,"<="&$Q$1,'Form responses'!$D$2:$D63,$J$1) -> 0 | L5: =sumifs('Form responses'!R2:R63,'Form responses'!$C$2:$C63,">="&$N$1,'Form responses'!$C$2:$C63,"<="&$Q$1,'Form responses'!$D$2:$D63,$J$1) -> 0 | M5: =sumifs('Form responses'!S2:S63,'Form responses'!$C$2:$C63,">="&$N$1,'Form responses'!$C$2:$C63,"<="&$Q$1,'Form responses'!$D$2:$D63,$J$1) -> 0 | N5: =sumifs('Form responses'!T2:T63,'Form responses'!$C$2:$C63,">="&$N$1,'Form responses'!$C$2:$C63,"<="&$Q$1,'Form responses'!$D$2:$D63,$J$1) -> 0 | O5: =E5+F5+M5+N5 -> 40 | P5: =G5+H5+I5+J5 -> 40 | R5: =sumifs('Form responses'!U$2:U63,'Form responses'!$C$2:$C63,">="&$N$1,'Form responses'!$C$2:$C63,"<="&$Q$1,'Form responses'!$D$2:$D63,$J$1) -> 0 | S5: =sumifs('Form responses'!V$2:V63,'Form responses'!$C$2:$C63,">="&$N$1,'Form responses'!$C$2:$C63,"<="&$Q$1,'Form responses'!$D$2:$D63,$J$1) -> 0 | T5: =sumifs('Form responses'!W$2:W63,'Form responses'!$C$2:$C63,">="&$N$1,'Form responses'!$C$2:$C63,"<="&$Q$1,'Form responses'!$D$2:$D63,$J$1) -> 0 | U5: =sumifs('Form responses'!X$2:X63,'Form responses'!$C$2:$C63,">="&$N$1,'Form responses'!$C$2:$C63,"<="&$Q$1,'Form responses'!$D$2:$D63,$J$1) -> 0 | V5: =sumifs('Form responses'!Y$2:Y63,'Form responses'!$C$2:$C63,">="&$N$1,'Form responses'!$C$2:$C63,"<="&$Q$1,'Form responses'!$D$2:$D63,$J$1) -> 0 | W5: =sumifs('Form responses'!Z$2:Z63,'Form responses'!$C$2:$C63,">="&$N$1,'Form responses'!$C$2:$C63,"<="&$Q$1,'Form responses'!$D$2:$D63,$J$1) -> 0 | X5: =sumifs('Form responses'!AA$2:AA63,'Form responses'!$C$2:$C63,">="&$N$1,'Form responses'!$C$2:$C63,"<="&$Q$1,'Form responses'!$D$2:$D63,$J$1) -> 0 | Y5: =sumifs('Form responses'!AB$2:AB63,'Form responses'!$C$2:$C63,">="&$N$1,'Form responses'!$C$2:$C63,"<="&$Q$1,'Form responses'!$D$2:$D63,$J$1) -> 0 | ... AA5: =sumifs('Form responses'!AD$2:AD63,'Form responses'!$C$2:$C63,">="&$N$1,'Form responses'!$C$2:$C63,"<="&$Q$1,'Form responses'!$D$2:$D63,$J$1) -> 0
B6: =sumifs('Form responses'!I2:I63,'Form responses'!$C$2:$C63,"<="&$Q$1,'Form responses'!$C$2:$C63,">="&Date(YEAR(DATE(YEAR($N$1),MONTH($N$1)+(-3),1)),4,1),'Form responses'!$D$2:$D63,$J$1) -> 0 | C6: =sumifs('Form responses'!J2:J63,'Form responses'!$C$2:$C63,"<="&$Q$1,'Form responses'!$C$2:$C63,">="&Date(YEAR(DATE(YEAR($N$1),MONTH($N$1)+(-3),1)),4,1),'Form responses'!$D$2:$D63,$J$1) -> 40 | D6: =sumifs('Form responses'!K2:K63,'Form responses'!$C$2:$C63,"<="&$Q$1,'Form responses'!$C$2:$C63,">="&Date(YEAR(DATE(YEAR($N$1),MONTH($N$1)+(-3),1)),4,1),'Form responses'!$D$2:$D63,$J$1) -> 0 | E6: =SUM(B6:D6) -> 40 | F6: =sumifs('Form responses'!L2:L63,'Form responses'!$C$2:$C63,"<="&$Q$1,'Form responses'!$C$2:$C63,">="&Date(YEAR(DATE(YEAR($N$1),MONTH($N$1)+(-3),1)),4,1),'Form responses'!$D$2:$D63,$J$1) -> 0 | G6: =sumifs('Form responses'!M2:M63,'Form responses'!$C$2:$C63,"<="&$Q$1,'Form responses'!$C$2:$C63,">="&Date(YEAR(DATE(YEAR($N$1),MONTH($N$1)+(-3),1)),4,1),'Form responses'!$D$2:$D63,$J$1) -> 0 | H6: =sumifs('Form responses'!N2:N63,'Form responses'!$C$2:$C63,"<="&$Q$1,'Form responses'!$C$2:$C63,">="&Date(YEAR(DATE(YEAR($N$1),MONTH($N$1)+(-3),1)),4,1),'Form responses'!$D$2:$D63,$J$1) -> 40 | I6: =sumifs('Form responses'!O2:O63,'Form responses'!$C$2:$C63,"<="&$Q$1,'Form responses'!$C$2:$C63,">="&Date(YEAR(DATE(YEAR($N$1),MONTH($N$1)+(-3),1)),4,1),'Form responses'!$D$2:$D63,$J$1) -> 0 | J6: =sumifs('Form responses'!P2:P63,'Form responses'!$C$2:$C63,"<="&$Q$1,'Form responses'!$C$2:$C63,">="&Date(YEAR(DATE(YEAR($N$1),MONTH($N$1)+(-3),1)),4,1),'Form responses'!$D$2:$D63,$J$1) -> 0 | K6: =sumifs('Form responses'!Q2:Q63,'Form responses'!$C$2:$C63,"<="&$Q$1,'Form responses'!$C$2:$C63,">="&Date(YEAR(DATE(YEAR($N$1),MONTH($N$1)+(-3),1)),4,1),'Form responses'!$D$2:$D63,$J$1) -> 0 | L6: =sumifs('Form responses'!R2:R63,'Form responses'!$C$2:$C63,"<="&$Q$1,'Form responses'!$C$2:$C63,">="&Date(YEAR(DATE(YEAR($N$1),MONTH($N$1)+(-3),1)),4,1),'Form responses'!$D$2:$D63,$J$1) -> 0 | M6: =sumifs('Form responses'!S2:S63,'Form responses'!$C$2:$C63,"<="&$Q$1,'Form responses'!$C$2:$C63,">="&Date(YEAR(DATE(YEAR($N$1),MONTH($N$1)+(-3),1)),4,1),'Form responses'!$D$2:$D63,$J$1) -> 0 | N6: =sumifs('Form responses'!T2:T63,'Form responses'!$C$2:$C63,"<="&$Q$1,'Form responses'!$C$2:$C63,">="&Date(YEAR(DATE(YEAR($N$1),MONTH($N$1)+(-3),1)),4,1),'Form responses'!$D$2:$D63,$J$1) -> 0 | O6: =E6+F6+M6+N6 -> 40 | P6: =G6+H6+I6+J6 -> 40 | R6: =sumifs('Form responses'!U$2:U63,'Form responses'!$C$2:$C63,">="&Date(YEAR(DATE(YEAR($Q$1),MONTH($Q$1)+(-3),1)),4,1),'Form responses'!$C$2:$C63,"<="&$Q$1,'Form responses'!$D$2:$D63,$J$1) -> 0 | S6: =sumifs('Form responses'!V$2:V63,'Form responses'!$C$2:$C63,">="&Date(YEAR(DATE(YEAR($Q$1),MONTH($Q$1)+(-3),1)),4,1),'Form responses'!$C$2:$C63,"<="&$Q$1,'Form responses'!$D$2:$D63,$J$1) -> 0 | T6: =sumifs('Form responses'!W$2:W63,'Form responses'!$C$2:$C63,">="&Date(YEAR(DATE(YEAR($Q$1),MONTH($Q$1)+(-3),1)),4,1),'Form responses'!$C$2:$C63,"<="&$Q$1,'Form responses'!$D$2:$D63,$J$1) -> 0 | U6: =sumifs('Form responses'!X$2:X63,'Form responses'!$C$2:$C63,">="&Date(YEAR(DATE(YEAR($Q$1),MONTH($Q$1)+(-3),1)),4,1),'Form responses'!$C$2:$C63,"<="&$Q$1,'Form responses'!$D$2:$D63,$J$1) -> 0 | V6: =sumifs('Form responses'!Y$2:Y63,'Form responses'!$C$2:$C63,">="&Date(YEAR(DATE(YEAR($Q$1),MONTH($Q$1)+(-3),1)),4,1),'Form responses'!$C$2:$C63,"<="&$Q$1,'Form responses'!$D$2:$D63,$J$1) -> 0 | W6: =sumifs('Form responses'!Z$2:Z63,'Form responses'!$C$2:$C63,">="&Date(YEAR(DATE(YEAR($Q$1),MONTH($Q$1)+(-3),1)),4,1),'Form responses'!$C$2:$C63,"<="&$Q$1,'Form responses'!$D$2:$D63,$J$1) -> 0 | X6: =sumifs('Form responses'!AA$2:AA63,'Form responses'!$C$2:$C63,">="&Date(YEAR(DATE(YEAR($Q$1),MONTH($Q$1)+(-3),1)),4,1),'Form responses'!$C$2:$C63,"<="&$Q$1,'Form responses'!$D$2:$D63,$J$1) -> 0 | Y6: =sumifs('Form responses'!AB$2:AB63,'Form responses'!$C$2:$C63,">="&Date(YEAR(DATE(YEAR($Q$1),MONTH($Q$1)+(-3),1)),4,1),'Form responses'!$C$2:$C63,"<="&$Q$1,'Form responses'!$D$2:$D63,$J$1) -> 0 | ... AA6: =sumifs('Form responses'!AD$2:AD63,'Form responses'!$C$2:$C63,">="&Date(YEAR(DATE(YEAR($Q$1),MONTH($Q$1)+(-3),1)),4,1),'Form responses'!$C$2:$C63,"<="&$Q$1,'Form responses'!$D$2:$D63,$J$1) -> 0
B7: VACCINATION REPORT
B8: ='Form responses'!AE1 -> H.S. Vaccine Doses Received | C8: ='Form responses'!AF1 -> H.S. Vaccine Doses Used | D8: ='Form responses'!AG1 -> H.S. Vaccine Animal Vaccinated | E8: ='Form responses'!AH1 -> FMD. Vaccine Doses Received | F8: ='Form responses'!AI1 -> FMD. Vaccine Doses Used | G8: ='Form responses'!AJ1 -> FMD. Vaccine Animal Vaccinated | H8: ='Form responses'!AK1 -> Black Quarter Doses Received | I8: ='Form responses'!AL1 -> Black Quarter Doses Used | ... AA8: ='Form responses'!BD1 -> Rabies Doses Used
B9: =sumifs('Form responses'!AE$2:AE63,'Form responses'!$C$2:$C63,">="&$N$1,'Form responses'!$C$2:$C63,"<="&$Q$1,'Form responses'!$D$2:$D63,$J$1) -> 0 | C9: =sumifs('Form responses'!AF$2:AF63,'Form responses'!$C$2:$C63,">="&$N$1,'Form responses'!$C$2:$C63,"<="&$Q$1,'Form responses'!$D$2:$D63,$J$1) -> 0 | D9: =sumifs('Form responses'!AG$2:AG63,'Form responses'!$C$2:$C63,">="&$N$1,'Form responses'!$C$2:$C63,"<="&$Q$1,'Form responses'!$D$2:$D63,$J$1) -> 0 | E9: =sumifs('Form responses'!AH$2:AH63,'Form responses'!$C$2:$C63,">="&$N$1,'Form responses'!$C$2:$C63,"<="&$Q$1,'Form responses'!$D$2:$D63,$J$1) -> 0 | F9: =sumifs('Form responses'!AI$2:AI63,'Form responses'!$C$2:$C63,">="&$N$1,'Form responses'!$C$2:$C63,"<="&$Q$1,'Form responses'!$D$2:$D63,$J$1) -> 1300 | G9: =sumifs('Form responses'!AJ$2:AJ63,'Form responses'!$C$2:$C63,">="&$N$1,'Form responses'!$C$2:$C63,"<="&$Q$1,'Form responses'!$D$2:$D63,$J$1) -> 1300 | H9: =sumifs('Form responses'!AK$2:AK63,'Form responses'!$C$2:$C63,">="&$N$1,'Form responses'!$C$2:$C63,"<="&$Q$1,'Form responses'!$D$2:$D63,$J$1) -> 50 | I9: =sumifs('Form responses'!AL$2:AL63,'Form responses'!$C$2:$C63,">="&$N$1,'Form responses'!$C$2:$C63,"<="&$Q$1,'Form responses'!$D$2:$D63,$J$1) -> 50 | ... AA9: =sumifs('Form responses'!BD$2:BD63,'Form responses'!$C$2:$C63,">="&$N$1,'Form responses'!$C$2:$C63,"<="&$Q$1,'Form responses'!$D$2:$D63,$J$1) -> 0
B10: =sumifs('Form responses'!AE$2:AE63,'Form responses'!$C$2:$C63,">="&Date(YEAR(DATE(YEAR($Q$1),MONTH($Q$1)+(-3),1)),4,1),'Form responses'!$C$2:$C63,"<="&$Q$1,'Form responses'!$D$2:$D63,$J$1) -> 0 | C10: =sumifs('Form responses'!AF$2:AF63,'Form responses'!$C$2:$C63,">="&Date(YEAR(DATE(YEAR($Q$1),MONTH($Q$1)+(-3),1)),4,1),'Form responses'!$C$2:$C63,"<="&$Q$1,'Form responses'!$D$2:$D63,$J$1) -> 0 | D10: =sumifs('Form responses'!AG$2:AG63,'Form responses'!$C$2:$C63,">="&Date(YEAR(DATE(YEAR($Q$1),MONTH($Q$1)+(-3),1)),4,1),'Form responses'!$C$2:$C63,"<="&$Q$1,'Form responses'!$D$2:$D63,$J$1) -> 0 | E10: =sumifs('Form responses'!AH$2:AH63,'Form responses'!$C$2:$C63,">="&Date(YEAR(DATE(YEAR($Q$1),MONTH($Q$1)+(-3),1)),4,1),'Form responses'!$C$2:$C63,"<="&$Q$1,'Form responses'!$D$2:$D63,$J$1) -> 0 | F10: =sumifs('Form responses'!AI$2:AI63,'Form responses'!$C$2:$C63,">="&Date(YEAR(DATE(YEAR($Q$1),MONTH($Q$1)+(-3),1)),4,1),'Form responses'!$C$2:$C63,"<="&$Q$1,'Form responses'!$D$2:$D63,$J$1) -> 1300 | G10: =sumifs('Form responses'!AJ$2:AJ63,'Form responses'!$C$2:$C63,">="&Date(YEAR(DATE(YEAR($Q$1),MONTH($Q$1)+(-3),1)),4,1),'Form responses'!$C$2:$C63,"<="&$Q$1,'Form responses'!$D$2:$D63,$J$1) -> 1300 | H10: =sumifs('Form responses'!AK$2:AK63,'Form responses'!$C$2:$C63,">="&Date(YEAR(DATE(YEAR($Q$1),MONTH($Q$1)+(-3),1)),4,1),'Form responses'!$C$2:$C63,"<="&$Q$1,'Form responses'!$D$2:$D63,$J$1) -> 50 | I10: =sumifs('Form responses'!AL$2:AL63,'Form responses'!$C$2:$C63,">="&Date(YEAR(DATE(YEAR($Q$1),MONTH($Q$1)+(-3),1)),4,1),'Form responses'!$C$2:$C63,"<="&$Q$1,'Form responses'!$D$2:$D63,$J$1) -> 50 | ... AA10: =sumifs('Form responses'!BD$2:BD63,'Form responses'!$C$2:$C63,">="&Date(YEAR(DATE(YEAR($Q$1),MONTH($Q$1)+(-3),1)),4,1),'Form responses'!$C$2:$C63,"<="&$Q$1,'Form responses'!$D$2:$D63,$J$1) -> 0
B11: =sumifs('Form responses'!AE2:AE63, 'Form responses'!$C$2:$C63, "<="&$Q$1, 'Form responses'!$D$2:$D63,$J$1)-(sumifs('Form responses'!AF2:AF63, 'Form responses'!$C$2:$C63, "<="&$Q$1, 'Form responses'!$D$2:$D63,$J$1)) -> 0 | E11: =sumifs('Form responses'!AH2:AH63, 'Form responses'!$C$2:$C63, "<="&$Q$1, 'Form responses'!$D$2:$D63,$J$1)-(sumifs('Form responses'!AI2:AI63, 'Form responses'!$C$2:$C63, "<="&$Q$1, 'Form responses'!$D$2:$D63,$J$1)) -> 3750 | H11: =sumifs('Form responses'!AK2:AK63, 'Form responses'!$C$2:$C63, "<="&$Q$1, 'Form responses'!$D$2:$D63,$J$1)-(sumifs('Form responses'!AL2:AL63, 'Form responses'!$C$2:$C63, "<="&$Q$1, 'Form responses'!$D$2:$D63,$J$1)) -> 0 | K11: =sumifs('Form responses'!AN2:AN63, 'Form responses'!$C$2:$C63, "<="&$Q$1, 'Form responses'!$D$2:$D63,$J$1)-(sumifs('Form responses'!AO2:AO63, 'Form responses'!$C$2:$C63, "<="&$Q$1, 'Form responses'!$D$2:$D63,$J$1)) -> 500 | N11: =sumifs('Form responses'!AQ2:AQ63, 'Form responses'!$C$2:$C63, "<="&$Q$1, 'Form responses'!$D$2:$D63,$J$1)-(sumifs('Form responses'!AR2:AR63, 'Form responses'!$C$2:$C63, "<="&$Q$1, 'Form responses'!$D$2:$D63,$J$1)) -> 0 | Q11: =sumifs('Form responses'!AT2:AT63, 'Form responses'!$C$2:$C63, "<="&$Q$1, 'Form responses'!$D$2:$D63,$J$1)-(sumifs('Form responses'!AU2:AU63, 'Form responses'!$C$2:$C63, "<="&$Q$1, 'Form responses'!$D$2:$D63,$J$1)) -> 0 | T11: =sumifs('Form responses'!AW2:AW63, 'Form responses'!$C$2:$C63, "<="&$Q$1, 'Form responses'!$D$2:$D63,$J$1)-(sumifs('Form responses'!AX2:AX63, 'Form responses'!$C$2:$C63, "<="&$Q$1, 'Form responses'!$D$2:$D63,$J$1)) -> 0 | W11: =sumifs('Form responses'!AZ2:AZ63, 'Form responses'!$C$2:$C63, "<="&$Q$1, 'Form responses'!$D$2:$D63,$J$1)-(sumifs('Form responses'!BA2:BA63, 'Form responses'!$C$2:$C63, "<="&$Q$1, 'Form responses'!$D$2:$D63,$J$1)) -> 0 | Z11: =sumifs('Form responses'!BC2:BC63, 'Form responses'!$C$2:$C63, "<="&$Q$1, 'Form responses'!$D$2:$D63,$J$1)-(sumifs('Form responses'!BD2:BD63, 'Form responses'!$C$2:$C63, "<="&$Q$1, 'Form responses'!$D$2:$D63,$J$1)) -> 10
B12: A.I. WITH FROZEN SEMEN IN COWS
B13: ='Form responses'!BF1 -> AI HF Straws | C13: ='Form responses'!BG1 -> Cover HF Straws | D13: ='Form responses'!BH1 -> AI Jersey Straws | E13: ='Form responses'!BI1 -> Cover Jersey Straws | F13: ='Form responses'!BJ1 -> AI Cross Breed Straws | G13: ='Form responses'!BK1 -> Cover Cross Breed Straws | H13: ='Form responses'!BL1 -> AI Sahiwal Straws | I13: ='Form responses'!BM1 -> Cover Sahiwal Straws | J13: Total AI Done | L13: ='Form responses'!BN1 -> AI HF ETT Straws | M13: ='Form responses'!BO1 -> Cover HF ETT Straws | N13: ='Form responses'!BP1 -> AI Jersey ETT Straws | O13: ='Form responses'!BQ1 -> Cover Jersey ETT Straws | P13: Total ETT AI Done | R13: ='Form responses'!BR1 -> AI Sexed HF Straws | S13: ='Form responses'!BS1 -> Cover Sexed HF Straws | T13: ='Form responses'!BT1 -> AI Jersey Sexed Straws | U13: ='Form responses'!BU1 -> Cow Cover Jersey Sexed | V13: ='Form responses'!BV1 -> AI Cross Breed Sexed Straws | W13: ='Form responses'!BW1 -> Cover Cross Breed Sexed | X13: ='Form responses'!BX1 -> AI Sahiwal Sexed Straws | Y13: ='Form responses'!BY1 -> Cow Cover Sahiwal Sexed | Z13: Total Sexed AI Done
B14: =sumifs('Form responses'!BF$2:BF63,'Form responses'!$C$2:$C63,">="&$N$1,'Form responses'!$C$2:$C63,"<="&$Q$1,'Form responses'!$D$2:$D63,$J$1) -> 0 | C14: =sumifs('Form responses'!BG$2:BG63,'Form responses'!$C$2:$C63,">="&$N$1,'Form responses'!$C$2:$C63,"<="&$Q$1,'Form responses'!$D$2:$D63,$J$1) -> 0 | D14: =sumifs('Form responses'!BH$2:BH63,'Form responses'!$C$2:$C63,">="&$N$1,'Form responses'!$C$2:$C63,"<="&$Q$1,'Form responses'!$D$2:$D63,$J$1) -> 0 | E14: =sumifs('Form responses'!BI$2:BI63,'Form responses'!$C$2:$C63,">="&$N$1,'Form responses'!$C$2:$C63,"<="&$Q$1,'Form responses'!$D$2:$D63,$J$1) -> 0 | F14: =sumifs('Form responses'!BJ$2:BJ63,'Form responses'!$C$2:$C63,">="&$N$1,'Form responses'!$C$2:$C63,"<="&$Q$1,'Form responses'!$D$2:$D63,$J$1) -> 0 | G14: =sumifs('Form responses'!BK$2:BK63,'Form responses'!$C$2:$C63,">="&$N$1,'Form responses'!$C$2:$C63,"<="&$Q$1,'Form responses'!$D$2:$D63,$J$1) -> 0 | H14: =sumifs('Form responses'!BL$2:BL63,'Form responses'!$C$2:$C63,">="&$N$1,'Form responses'!$C$2:$C63,"<="&$Q$1,'Form responses'!$D$2:$D63,$J$1) -> 0 | I14: =sumifs('Form responses'!BM$2:BM63,'Form responses'!$C$2:$C63,">="&$N$1,'Form responses'!$C$2:$C63,"<="&$Q$1,'Form responses'!$D$2:$D63,$J$1) -> 0 | J14: =B14+D14+F14+H14 -> 0 | L14: =sumifs('Form responses'!BN$2:BN63,'Form responses'!$C$2:$C63,">="&$N$1,'Form responses'!$C$2:$C63,"<="&$Q$1,'Form responses'!$D$2:$D63,$J$1) -> 0 | M14: =sumifs('Form responses'!BO$2:BO63,'Form responses'!$C$2:$C63,">="&$N$1,'Form responses'!$C$2:$C63,"<="&$Q$1,'Form responses'!$D$2:$D63,$J$1) -> 0 | N14: =sumifs('Form responses'!BP$2:BP63,'Form responses'!$C$2:$C63,">="&$N$1,'Form responses'!$C$2:$C63,"<="&$Q$1,'Form responses'!$D$2:$D63,$J$1) -> 0 | O14: =sumifs('Form responses'!BQ$2:BQ63,'Form responses'!$C$2:$C63,">="&$N$1,'Form responses'!$C$2:$C63,"<="&$Q$1,'Form responses'!$D$2:$D63,$J$1) -> 0 | P14: =L14+N14 -> 0 | R14: =sumifs('Form responses'!BR$2:BR63,'Form responses'!$C$2:$C63,">="&$N$1,'Form responses'!$C$2:$C63,"<="&$Q$1,'Form responses'!$D$2:$D63,$J$1) -> 0 | S14: =sumifs('Form responses'!BS$2:BS63,'Form responses'!$C$2:$C63,">="&$N$1,'Form responses'!$C$2:$C63,"<="&$Q$1,'Form responses'!$D$2:$D63,$J$1) -> 0 | T14: =sumifs('Form responses'!BT$2:BT63,'Form responses'!$C$2:$C63,">="&$N$1,'Form responses'!$C$2:$C63,"<="&$Q$1,'Form responses'!$D$2:$D63,$J$1) -> 0 | U14: =sumifs('Form responses'!BU$2:BU63,'Form responses'!$C$2:$C63,">="&$N$1,'Form responses'!$C$2:$C63,"<="&$Q$1,'Form responses'!$D$2:$D63,$J$1) -> 0 | V14: =sumifs('Form responses'!BV$2:BV63,'Form responses'!$C$2:$C63,">="&$N$1,'Form responses'!$C$2:$C63,"<="&$Q$1,'Form responses'!$D$2:$D63,$J$1) -> 0 | W14: =sumifs('Form responses'!BW$2:BW63,'Form responses'!$C$2:$C63,">="&$N$1,'Form responses'!$C$2:$C63,"<="&$Q$1,'Form responses'!$D$2:$D63,$J$1) -> 0 | X14: =sumifs('Form responses'!BX$2:BX63,'Form responses'!$C$2:$C63,">="&$N$1,'Form responses'!$C$2:$C63,"<="&$Q$1,'Form responses'!$D$2:$D63,$J$1) -> 0 | Y14: =sumifs('Form responses'!BY$2:BY63,'Form responses'!$C$2:$C63,">="&$N$1,'Form responses'!$C$2:$C63,"<="&$Q$1,'Form responses'!$D$2:$D63,$J$1) -> 0 | Z14: =R14+T14+V14+X14 -> 0
